5:return {{["x"] = 0, ["meta"] = {["inventory"] = {}, ["fields"] = {}}, ["y"] = 0, ["name"] = "default:water_source", ["z"] = 0, ["param1"] = 13}, {["x"] = 0, ["meta"] = {["inventory"] = {}, ["fields"] = {}}, ["y"] = 0, ["name"] = "default:water_source", ["z"] = 1, ["param1"] = 13}, {["x"] = 0, ["meta"] = {["inventory"] = {}, ["fields"] = {}}, ["y"] = 0, ["name"] = "default:water_source", ["z"] = 2, ["param1"] = 14}, {["x"] = 0, ["meta"] = {["inventory"] = {}, ["fields"] = {}}, ["y"] = 0, ["name"] = "default:water_source", ["z"] = 3, ["param1"] = 14}, {["x"] = 0, ["meta"] = {["inventory"] = {}, ["fields"] = {}}, ["y"] = 0, ["name"] = "default:water_source", ["z"] = 4, ["param1"] = 14}, {["x"] = 0, ["meta"] = {["inventory"] = {}, ["fields"] = {}}, ["y"] = 0, ["name"] = "default:water_source", ["z"] = 5, ["param1"] = 14}, {["x"] = 0, ["meta"] = {["inventory"] = {}, ["fields"] = {}}, ["y"] = 0, ["name"] = "default:water_source", ["z"] = 6, ["param1"] = 14}, {["x"] = 0, ["meta"] = {["inventory"] = {}, ["fields"] = {}}, ["y"] = 0, ["name"] = "default:water_source", ["z"] = 7, ["param1"] = 14}, {["x"] = 0, ["meta"] = {["inventory"] = {}, ["fields"] = {}}, ["y"] = 0, ["name"] = "default:water_source", ["z"] = 8, ["param1"] = 14}, {["x"] = 0, ["meta"] = {["inventory"] = {}, ["fields"] = {}}, ["y"] = 0, ["name"] = "default:water_source", ["z"] = 9, ["param1"] = 14}, {["x"] = 0, ["meta"] = {["inventory"] = {}, ["fields"] = {}}, ["y"] = 0, ["name"] = "default:water_source", ["z"] = 10, ["param1"] = 14}, {["x"] = 0, ["meta"] = {["inventory"] = {}, ["fields"] = {}}, ["y"] = 0, ["name"] = "default:water_source", ["z"] = 11, ["param1"] = 14}, {["x"] = 0, ["meta"] = {["inventory"] = {}, ["fields"] = {}}, ["y"] = 0, ["name"] = "default:water_source", ["z"] = 12, ["param1"] = 14}, {["x"] = 0, ["meta"] = {["inventory"] = {}, ["fields"] = {}}, ["y"] = 0, ["name"] = "default:water_source", ["z"] = 13, ["param1"] = 14}, {["x"] = 0, ["meta"] = {["inventory"] = {}, ["fields"] = {}}, ["y"] = 0, ["name"] = "default:water_source", ["z"] = 14, ["param1"] = 14}, {["x"] = 0, ["meta"] = {["inventory"] = {}, ["fields"] = {}}, ["y"] = 0, ["name"] = "default:water_source", ["z"] = 15, ["param1"] = 14}, {["x"] = 0, ["meta"] = {["inventory"] = {}, ["fields"] = {}}, ["y"] = 0, ["name"] = "default:water_source", ["z"] = 16, ["param1"] = 14}, {["x"] = 0, ["meta"] = {["inventory"] = {}, ["fields"] = {}}, ["param2"] = 1, ["y"] = 1, ["name"] = "default:water_flowing", ["z"] = 0, ["param1"] = 14}, {["x"] = 0, ["meta"] = {["inventory"] = {}, ["fields"] = {}}, ["y"] = 1, ["name"] = "default:water_flowing", ["z"] = 1, ["param1"] = 14}, {["x"] = 1, ["meta"] = {["inventory"] = {}, ["fields"] = {}}, ["y"] = 0, ["name"] = "default:water_source", ["z"] = 0, ["param1"] = 13}, {["x"] = 1, ["meta"] = {["inventory"] = {}, ["fields"] = {}}, ["y"] = 0, ["name"] = "default:water_source", ["z"] = 1, ["param1"] = 14}, {["x"] = 1, ["meta"] = {["inventory"] = {}, ["fields"] = {}}, ["y"] = 0, ["name"] = "default:water_source", ["z"] = 2, ["param1"] = 14}, {["x"] = 1, ["meta"] = {["inventory"] = {}, ["fields"] = {}}, ["y"] = 0, ["name"] = "default:water_source", ["z"] = 3, ["param1"] = 14}, {["x"] = 1, ["meta"] = {["inventory"] = {}, ["fields"] = {}}, ["y"] = 0, ["name"] = "default:water_source", ["z"] = 4, ["param1"] = 14}, {["x"] = 1, ["meta"] = {["inventory"] = {}, ["fields"] = {}}, ["y"] = 0, ["name"] = "default:water_source", ["z"] = 5, ["param1"] = 14}, {["x"] = 1, ["meta"] = {["inventory"] = {}, ["fields"] = {}}, ["y"] = 0, ["name"] = "default:water_source", ["z"] = 6, ["param1"] = 14}, {["x"] = 1, ["meta"] = {["inventory"] = {}, ["fields"] = {}}, ["y"] = 0, ["name"] = "default:water_source", ["z"] = 7, ["param1"] = 14}, {["x"] = 1, ["meta"] = {["inventory"] = {}, ["fields"] = {}}, ["y"] = 0, ["name"] = "default:water_source", ["z"] = 8, ["param1"] = 14}, {["x"] = 1, ["meta"] = {["inventory"] = {}, ["fields"] = {}}, ["y"] = 0, ["name"] = "default:water_source", ["z"] = 9, ["param1"] = 14}, {["x"] = 1, ["meta"] = {["inventory"] = {}, ["fields"] = {}}, ["y"] = 0, ["name"] = "default:water_source", ["z"] = 10, ["param1"] = 14}, {["x"] = 1, ["meta"] = {["inventory"] = {}, ["fields"] = {}}, ["y"] = 0, ["name"] = "default:water_source", ["z"] = 11, ["param1"] = 14}, {["x"] = 1, ["meta"] = {["inventory"] = {}, ["fields"] = {}}, ["y"] = 0, ["name"] = "default:water_source", ["z"] = 12, ["param1"] = 14}, {["x"] = 1, ["meta"] = {["inventory"] = {}, ["fields"] = {}}, ["y"] = 0, ["name"] = "default:water_source", ["z"] = 13, ["param1"] = 14}, {["x"] = 1, ["meta"] = {["inventory"] = {}, ["fields"] = {}}, ["y"] = 0, ["name"] = "default:water_source", ["z"] = 14, ["param1"] = 14}, {["x"] = 1, ["meta"] = {["inventory"] = {}, ["fields"] = {}}, ["y"] = 0, ["name"] = "default:water_source", ["z"] = 15, ["param1"] = 14}, {["x"] = 1, ["meta"] = {["inventory"] = {}, ["fields"] = {}}, ["y"] = 0, ["name"] = "default:water_source", ["z"] = 16, ["param1"] = 14}, {["x"] = 1, ["meta"] = {["inventory"] = {}, ["fields"] = {}}, ["y"] = 1, ["name"] = "default:water_flowing", ["z"] = 0, ["param1"] = 14}, {["x"] = 2, ["meta"] = {["inventory"] = {}, ["fields"] = {}}, ["y"] = 0, ["name"] = "default:water_source", ["z"] = 0, ["param1"] = 14}, {["x"] = 2, ["meta"] = {["inventory"] = {}, ["fields"] = {}}, ["y"] = 0, ["name"] = "default:water_source", ["z"] = 1, ["param1"] = 14}, {["x"] = 2, ["meta"] = {["inventory"] = {}, ["fields"] = {}}, ["y"] = 0, ["name"] = "default:water_source", ["z"] = 2, ["param1"] = 14}, {["x"] = 2, ["meta"] = {["inventory"] = {}, ["fields"] = {}}, ["y"] = 0, ["name"] = "default:water_source", ["z"] = 3, ["param1"] = 13}, {["x"] = 2, ["meta"] = {["inventory"] = {}, ["fields"] = {}}, ["y"] = 0, ["name"] = "default:water_source", ["z"] = 4, ["param1"] = 13}, {["x"] = 2, ["meta"] = {["inventory"] = {}, ["fields"] = {}}, ["y"] = 0, ["name"] = "default:water_source", ["z"] = 5, ["param1"] = 13}, {["x"] = 2, ["meta"] = {["inventory"] = {}, ["fields"] = {}}, ["y"] = 0, ["name"] = "default:water_source", ["z"] = 6, ["param1"] = 13}, {["x"] = 2, ["meta"] = {["inventory"] = {}, ["fields"] = {}}, ["y"] = 0, ["name"] = "default:water_source", ["z"] = 7, ["param1"] = 13}, {["x"] = 2, ["meta"] = {["inventory"] = {}, ["fields"] = {}}, ["y"] = 0, ["name"] = "default:water_source", ["z"] = 8, ["param1"] = 13}, {["x"] = 2, ["meta"] = {["inventory"] = {}, ["fields"] = {}}, ["y"] = 0, ["name"] = "default:water_source", ["z"] = 9, ["param1"] = 13}, {["x"] = 2, ["meta"] = {["inventory"] = {}, ["fields"] = {}}, ["y"] = 0, ["name"] = "default:water_source", ["z"] = 10, ["param1"] = 13}, {["x"] = 2, ["meta"] = {["inventory"] = {}, ["fields"] = {}}, ["y"] = 0, ["name"] = "default:water_source", ["z"] = 11, ["param1"] = 13}, {["x"] = 2, ["meta"] = {["inventory"] = {}, ["fields"] = {}}, ["y"] = 0, ["name"] = "default:water_source", ["z"] = 12, ["param1"] = 13}, {["x"] = 2, ["meta"] = {["inventory"] = {}, ["fields"] = {}}, ["y"] = 0, ["name"] = "default:water_source", ["z"] = 13, ["param1"] = 14}, {["x"] = 2, ["meta"] = {["inventory"] = {}, ["fields"] = {}}, ["y"] = 0, ["name"] = "default:water_source", ["z"] = 14, ["param1"] = 14}, {["x"] = 2, ["meta"] = {["inventory"] = {}, ["fields"] = {}}, ["y"] = 0, ["name"] = "default:water_source", ["z"] = 15, ["param1"] = 14}, {["x"] = 2, ["meta"] = {["inventory"] = {}, ["fields"] = {}}, ["y"] = 0, ["name"] = "default:water_source", ["z"] = 16, ["param1"] = 14}, {["x"] = 2, ["meta"] = {["inventory"] = {}, ["fields"] = {}}, ["param2"] = 20, ["y"] = 17, ["name"] = "building_blocks:slope_hardwood_outer_half_raised", ["z"] = 3, ["param1"] = 14}, {["x"] = 2, ["meta"] = {["inventory"] = {}, ["fields"] = {}}, ["param2"] = 23, ["y"] = 17, ["name"] = "building_blocks:slope_hardwood_half_raised", ["z"] = 4, ["param1"] = 14}, {["x"] = 2, ["meta"] = {["inventory"] = {}, ["fields"] = {}}, ["param2"] = 23, ["y"] = 17, ["name"] = "building_blocks:slope_hardwood_half_raised", ["z"] = 5, ["param1"] = 30}, {["x"] = 2, ["meta"] = {["inventory"] = {}, ["fields"] = {}}, ["param2"] = 23, ["y"] = 17, ["name"] = "building_blocks:slope_hardwood_half_raised", ["z"] = 6, ["param1"] = 46}, {["x"] = 2, ["meta"] = {["inventory"] = {}, ["fields"] = {}}, ["param2"] = 23, ["y"] = 17, ["name"] = "building_blocks:slope_hardwood_half_raised", ["z"] = 7, ["param1"] = 62}, {["x"] = 2, ["meta"] = {["inventory"] = {}, ["fields"] = {}}, ["param2"] = 23, ["y"] = 17, ["name"] = "building_blocks:slope_hardwood_half_raised", ["z"] = 8, ["param1"] = 78}, {["x"] = 2, ["meta"] = {["inventory"] = {}, ["fields"] = {}}, ["param2"] = 23, ["y"] = 17, ["name"] = "building_blocks:slope_hardwood_half_raised", ["z"] = 9, ["param1"] = 94}, {["x"] = 2, ["meta"] = {["inventory"] = {}, ["fields"] = {}}, ["param2"] = 23, ["y"] = 17, ["name"] = "building_blocks:slope_hardwood_half_raised", ["z"] = 10, ["param1"] = 110}, {["x"] = 2, ["meta"] = {["inventory"] = {}, ["fields"] = {}}, ["param2"] = 23, ["y"] = 17, ["name"] = "building_blocks:slope_hardwood_half_raised", ["z"] = 11, ["param1"] = 94}, {["x"] = 2, ["meta"] = {["inventory"] = {}, ["fields"] = {}}, ["param2"] = 23, ["y"] = 17, ["name"] = "building_blocks:slope_hardwood_half_raised", ["z"] = 12, ["param1"] = 78}, {["x"] = 2, ["meta"] = {["inventory"] = {}, ["fields"] = {}}, ["y"] = 18, ["name"] = "ethereal:fence_redwood", ["z"] = 3, ["param1"] = 15}, {["x"] = 2, ["meta"] = {["inventory"] = {}, ["fields"] = {}}, ["y"] = 18, ["name"] = "ethereal:fence_redwood", ["z"] = 4, ["param1"] = 31}, {["x"] = 2, ["meta"] = {["inventory"] = {}, ["fields"] = {}}, ["y"] = 18, ["name"] = "ethereal:fence_redwood", ["z"] = 5, ["param1"] = 47}, {["x"] = 2, ["meta"] = {["inventory"] = {}, ["fields"] = {}}, ["y"] = 18, ["name"] = "ethereal:fence_redwood", ["z"] = 6, ["param1"] = 63}, {["x"] = 2, ["meta"] = {["inventory"] = {}, ["fields"] = {}}, ["y"] = 18, ["name"] = "ethereal:fence_redwood", ["z"] = 7, ["param1"] = 79}, {["x"] = 2, ["meta"] = {["inventory"] = {}, ["fields"] = {}}, ["y"] = 18, ["name"] = "ethereal:fence_redwood", ["z"] = 8, ["param1"] = 95}, {["x"] = 2, ["meta"] = {["inventory"] = {}, ["fields"] = {}}, ["y"] = 18, ["name"] = "ethereal:fence_redwood", ["z"] = 9, ["param1"] = 111}, {["x"] = 2, ["meta"] = {["inventory"] = {}, ["fields"] = {}}, ["y"] = 18, ["name"] = "ethereal:fence_redwood", ["z"] = 10, ["param1"] = 127}, {["x"] = 2, ["meta"] = {["inventory"] = {}, ["fields"] = {}}, ["y"] = 18, ["name"] = "ethereal:fence_redwood", ["z"] = 11, ["param1"] = 111}, {["x"] = 2, ["meta"] = {["inventory"] = {}, ["fields"] = {}}, ["y"] = 18, ["name"] = "ethereal:fence_redwood", ["z"] = 12, ["param1"] = 95}, {["x"] = 2, ["meta"] = {["inventory"] = {}, ["fields"] = {}}, ["y"] = 18, ["name"] = "ethereal:fence_redwood", ["z"] = 13, ["param1"] = 79}, {["x"] = 3, ["meta"] = {["inventory"] = {}, ["fields"] = {}}, ["y"] = 0, ["name"] = "default:water_source", ["z"] = 0, ["param1"] = 14}, {["x"] = 3, ["meta"] = {["inventory"] = {}, ["fields"] = {}}, ["y"] = 0, ["name"] = "default:water_source", ["z"] = 1, ["param1"] = 14}, {["x"] = 3, ["meta"] = {["inventory"] = {}, ["fields"] = {}}, ["y"] = 0, ["name"] = "default:water_source", ["z"] = 2, ["param1"] = 14}, {["x"] = 3, ["meta"] = {["inventory"] = {}, ["fields"] = {}}, ["y"] = 0, ["name"] = "default:water_source", ["z"] = 3, ["param1"] = 13}, {["x"] = 3, ["meta"] = {["inventory"] = {}, ["fields"] = {}}, ["param2"] = 1, ["y"] = 0, ["name"] = "default:tree", ["z"] = 4}, {["x"] = 3, ["meta"] = {["inventory"] = {}, ["fields"] = {}}, ["y"] = 0, ["name"] = "default:water_source", ["z"] = 5, ["param1"] = 12}, {["x"] = 3, ["meta"] = {["inventory"] = {}, ["fields"] = {}}, ["y"] = 0, ["name"] = "default:water_source", ["z"] = 6, ["param1"] = 12}, {["x"] = 3, ["meta"] = {["inventory"] = {}, ["fields"] = {}}, ["y"] = 0, ["name"] = "default:water_source", ["z"] = 7, ["param1"] = 12}, {["x"] = 3, ["meta"] = {["inventory"] = {}, ["fields"] = {}}, ["y"] = 0, ["name"] = "default:water_source", ["z"] = 8, ["param1"] = 12}, {["x"] = 3, ["meta"] = {["inventory"] = {}, ["fields"] = {}}, ["y"] = 0, ["name"] = "default:water_source", ["z"] = 9, ["param1"] = 12}, {["x"] = 3, ["meta"] = {["inventory"] = {}, ["fields"] = {}}, ["y"] = 0, ["name"] = "default:water_source", ["z"] = 10, ["param1"] = 12}, {["x"] = 3, ["meta"] = {["inventory"] = {}, ["fields"] = {}}, ["y"] = 0, ["name"] = "default:water_source", ["z"] = 11, ["param1"] = 12}, {["x"] = 3, ["meta"] = {["inventory"] = {}, ["fields"] = {}}, ["param2"] = 1, ["y"] = 0, ["name"] = "default:tree", ["z"] = 12}, {["x"] = 3, ["meta"] = {["inventory"] = {}, ["fields"] = {}}, ["y"] = 0, ["name"] = "default:water_source", ["z"] = 13, ["param1"] = 13}, {["x"] = 3, ["meta"] = {["inventory"] = {}, ["fields"] = {}}, ["y"] = 0, ["name"] = "default:water_source", ["z"] = 14, ["param1"] = 14}, {["x"] = 3, ["meta"] = {["inventory"] = {}, ["fields"] = {}}, ["y"] = 0, ["name"] = "default:water_source", ["z"] = 15, ["param1"] = 14}, {["x"] = 3, ["meta"] = {["inventory"] = {}, ["fields"] = {}}, ["y"] = 0, ["name"] = "default:water_source", ["z"] = 16, ["param1"] = 14}, {["x"] = 3, ["meta"] = {["inventory"] = {}, ["fields"] = {}}, ["param2"] = 1, ["y"] = 1, ["name"] = "default:tree", ["z"] = 4}, {["x"] = 3, ["meta"] = {["inventory"] = {}, ["fields"] = {}}, ["param2"] = 1, ["y"] = 1, ["name"] = "default:tree", ["z"] = 12}, {["x"] = 3, ["meta"] = {["inventory"] = {}, ["fields"] = {}}, ["param2"] = 1, ["y"] = 2, ["name"] = "default:tree", ["z"] = 4}, {["x"] = 3, ["meta"] = {["inventory"] = {}, ["fields"] = {}}, ["param2"] = 1, ["y"] = 2, ["name"] = "default:tree", ["z"] = 12}, {["x"] = 3, ["meta"] = {["inventory"] = {}, ["fields"] = {}}, ["param2"] = 1, ["y"] = 3, ["name"] = "default:tree", ["z"] = 4}, {["x"] = 3, ["meta"] = {["inventory"] = {}, ["fields"] = {}}, ["param2"] = 1, ["y"] = 3, ["name"] = "default:tree", ["z"] = 12}, {["x"] = 3, ["meta"] = {["inventory"] = {}, ["fields"] = {}}, ["param2"] = 1, ["y"] = 4, ["name"] = "default:tree", ["z"] = 4}, {["x"] = 3, ["meta"] = {["inventory"] = {}, ["fields"] = {}}, ["param2"] = 1, ["y"] = 4, ["name"] = "default:tree", ["z"] = 12}, {["x"] = 3, ["meta"] = {["inventory"] = {}, ["fields"] = {}}, ["param2"] = 1, ["y"] = 5, ["name"] = "default:tree", ["z"] = 4}, {["x"] = 3, ["meta"] = {["inventory"] = {}, ["fields"] = {}}, ["param2"] = 1, ["y"] = 5, ["name"] = "default:tree", ["z"] = 12}, {["x"] = 3, ["meta"] = {["inventory"] = {}, ["fields"] = {}}, ["param2"] = 1, ["y"] = 6, ["name"] = "default:tree", ["z"] = 4}, {["x"] = 3, ["meta"] = {["inventory"] = {}, ["fields"] = {}}, ["param2"] = 1, ["y"] = 6, ["name"] = "default:tree", ["z"] = 12}, {["x"] = 3, ["meta"] = {["inventory"] = {}, ["fields"] = {}}, ["param2"] = 1, ["y"] = 7, ["name"] = "default:tree", ["z"] = 4}, {["x"] = 3, ["meta"] = {["inventory"] = {}, ["fields"] = {}}, ["param2"] = 1, ["y"] = 7, ["name"] = "default:tree", ["z"] = 12}, {["x"] = 3, ["meta"] = {["inventory"] = {}, ["fields"] = {}}, ["param2"] = 20, ["y"] = 16, ["name"] = "building_blocks:slope_hardwood_outer", ["z"] = 4, ["param1"] = 13}, {["x"] = 3, ["meta"] = {["inventory"] = {}, ["fields"] = {}}, ["param2"] = 17, ["y"] = 16, ["name"] = "building_blocks:slope_hardwood_half_raised", ["z"] = 5, ["param1"] = 13}, {["x"] = 3, ["meta"] = {["inventory"] = {}, ["fields"] = {}}, ["param2"] = 17, ["y"] = 16, ["name"] = "building_blocks:slope_hardwood_half_raised", ["z"] = 6, ["param1"] = 13}, {["x"] = 3, ["meta"] = {["inventory"] = {}, ["fields"] = {}}, ["param2"] = 17, ["y"] = 16, ["name"] = "building_blocks:slope_hardwood_half_raised", ["z"] = 7, ["param1"] = 29}, {["x"] = 3, ["meta"] = {["inventory"] = {}, ["fields"] = {}}, ["param2"] = 17, ["y"] = 16, ["name"] = "building_blocks:slope_hardwood_half_raised", ["z"] = 8, ["param1"] = 45}, {["x"] = 3, ["meta"] = {["inventory"] = {}, ["fields"] = {}}, ["param2"] = 17, ["y"] = 16, ["name"] = "building_blocks:slope_hardwood_half_raised", ["z"] = 9, ["param1"] = 61}, {["x"] = 3, ["meta"] = {["inventory"] = {}, ["fields"] = {}}, ["param2"] = 17, ["y"] = 16, ["name"] = "building_blocks:slope_hardwood_half_raised", ["z"] = 10, ["param1"] = 77}, {["x"] = 3, ["meta"] = {["inventory"] = {}, ["fields"] = {}}, ["param2"] = 17, ["y"] = 16, ["name"] = "building_blocks:slope_hardwood_half_raised", ["z"] = 11, ["param1"] = 61}, {["x"] = 3, ["meta"] = {["inventory"] = {}, ["fields"] = {}}, ["param2"] = 23, ["y"] = 16, ["name"] = "building_blocks:slope_hardwood_outer", ["z"] = 12, ["param1"] = 45}, {["x"] = 3, ["meta"] = {["inventory"] = {}, ["fields"] = {}}, ["param2"] = 20, ["y"] = 17, ["name"] = "building_blocks:slope_hardwood_half_raised", ["z"] = 3, ["param1"] = 14}, {["x"] = 3, ["meta"] = {["inventory"] = {}, ["fields"] = {}}, ["y"] = 17, ["name"] = "building_blocks:hardwood", ["z"] = 4, ["param1"] = 15}, {["x"] = 3, ["meta"] = {["inventory"] = {}, ["fields"] = {}}, ["y"] = 17, ["name"] = "building_blocks:hardwood", ["z"] = 5, ["param1"] = 15}, {["x"] = 3, ["meta"] = {["inventory"] = {}, ["fields"] = {}}, ["y"] = 17, ["name"] = "building_blocks:hardwood", ["z"] = 6, ["param1"] = 15}, {["x"] = 3, ["meta"] = {["inventory"] = {}, ["fields"] = {}}, ["y"] = 17, ["name"] = "building_blocks:hardwood", ["z"] = 7, ["param1"] = 15}, {["x"] = 3, ["meta"] = {["inventory"] = {}, ["fields"] = {}}, ["y"] = 17, ["name"] = "building_blocks:hardwood", ["z"] = 8, ["param1"] = 15}, {["x"] = 3, ["meta"] = {["inventory"] = {}, ["fields"] = {}}, ["y"] = 17, ["name"] = "building_blocks:hardwood", ["z"] = 9, ["param1"] = 15}, {["x"] = 3, ["meta"] = {["inventory"] = {}, ["fields"] = {}}, ["y"] = 17, ["name"] = "building_blocks:hardwood", ["z"] = 10, ["param1"] = 15}, {["x"] = 3, ["meta"] = {["inventory"] = {}, ["fields"] = {}}, ["y"] = 17, ["name"] = "building_blocks:hardwood", ["z"] = 11, ["param1"] = 15}, {["x"] = 3, ["meta"] = {["inventory"] = {}, ["fields"] = {}}, ["y"] = 17, ["name"] = "building_blocks:hardwood", ["z"] = 12, ["param1"] = 15}, {["x"] = 3, ["meta"] = {["inventory"] = {}, ["fields"] = {}}, ["param2"] = 22, ["y"] = 17, ["name"] = "building_blocks:slope_hardwood_half_raised", ["z"] = 13, ["param1"] = 78}, {["x"] = 3, ["meta"] = {["inventory"] = {}, ["fields"] = {}}, ["y"] = 18, ["name"] = "ethereal:fence_redwood", ["z"] = 3, ["param1"] = 31}, {["x"] = 3, ["meta"] = {["inventory"] = {}, ["fields"] = {}}, ["param2"] = 2, ["y"] = 18, ["name"] = "ethereal:vine", ["z"] = 9, ["param1"] = 126}, {["x"] = 3, ["meta"] = {["inventory"] = {}, ["fields"] = {}}, ["y"] = 18, ["name"] = "ethereal:fence_redwood", ["z"] = 13, ["param1"] = 95}, {["x"] = 3, ["meta"] = {["inventory"] = {}, ["fields"] = {}}, ["param2"] = 2, ["y"] = 19, ["name"] = "ethereal:vine", ["z"] = 7, ["param1"] = 78}, {["x"] = 3, ["meta"] = {["inventory"] = {}, ["fields"] = {}}, ["param2"] = 2, ["y"] = 19, ["name"] = "ethereal:vine", ["z"] = 9, ["param1"] = 110}, {["x"] = 3, ["meta"] = {["inventory"] = {}, ["fields"] = {}}, ["param2"] = 2, ["y"] = 20, ["name"] = "ethereal:vine", ["z"] = 7, ["param1"] = 62}, {["x"] = 3, ["meta"] = {["inventory"] = {}, ["fields"] = {}}, ["param2"] = 2, ["y"] = 20, ["name"] = "ethereal:vine", ["z"] = 9, ["param1"] = 94}, {["x"] = 3, ["meta"] = {["inventory"] = {}, ["fields"] = {}}, ["param2"] = 1, ["y"] = 21, ["name"] = "moreblocks:slope_copperpatina_outer_half", ["z"] = 4, ["param1"] = 14}, {["x"] = 3, ["meta"] = {["inventory"] = {}, ["fields"] = {}}, ["param2"] = 1, ["y"] = 21, ["name"] = "moreblocks:slope_copperpatina_half", ["z"] = 5, ["param1"] = 14}, {["x"] = 3, ["meta"] = {["inventory"] = {}, ["fields"] = {}}, ["param2"] = 1, ["y"] = 21, ["name"] = "moreblocks:slope_copperpatina_half", ["z"] = 6, ["param1"] = 30}, {["x"] = 3, ["meta"] = {["inventory"] = {}, ["fields"] = {}}, ["param2"] = 1, ["y"] = 21, ["name"] = "moreblocks:slope_copperpatina_half", ["z"] = 7, ["param1"] = 46}, {["x"] = 3, ["meta"] = {["inventory"] = {}, ["fields"] = {}}, ["param2"] = 1, ["y"] = 21, ["name"] = "moreblocks:slope_copperpatina_half", ["z"] = 8, ["param1"] = 62}, {["x"] = 3, ["meta"] = {["inventory"] = {}, ["fields"] = {}}, ["param2"] = 1, ["y"] = 21, ["name"] = "moreblocks:slope_copperpatina_half", ["z"] = 9, ["param1"] = 78}, {["x"] = 3, ["meta"] = {["inventory"] = {}, ["fields"] = {}}, ["param2"] = 1, ["y"] = 21, ["name"] = "moreblocks:slope_copperpatina_half", ["z"] = 10, ["param1"] = 94}, {["x"] = 3, ["meta"] = {["inventory"] = {}, ["fields"] = {}}, ["param2"] = 1, ["y"] = 21, ["name"] = "moreblocks:slope_copperpatina_half", ["z"] = 11, ["param1"] = 78}, {["x"] = 3, ["meta"] = {["inventory"] = {}, ["fields"] = {}}, ["param2"] = 2, ["y"] = 21, ["name"] = "moreblocks:slope_copperpatina_outer_half", ["z"] = 12, ["param1"] = 62}, {["x"] = 4, ["meta"] = {["inventory"] = {}, ["fields"] = {}}, ["y"] = 0, ["name"] = "default:water_source", ["z"] = 0, ["param1"] = 14}, {["x"] = 4, ["meta"] = {["inventory"] = {}, ["fields"] = {}}, ["y"] = 0, ["name"] = "default:water_source", ["z"] = 1, ["param1"] = 14}, {["x"] = 4, ["meta"] = {["inventory"] = {}, ["fields"] = {}}, ["y"] = 0, ["name"] = "default:water_source", ["z"] = 2, ["param1"] = 14}, {["x"] = 4, ["meta"] = {["inventory"] = {}, ["fields"] = {}}, ["y"] = 0, ["name"] = "default:water_source", ["z"] = 3, ["param1"] = 13}, {["x"] = 4, ["meta"] = {["inventory"] = {}, ["fields"] = {}}, ["y"] = 0, ["name"] = "default:water_source", ["z"] = 4, ["param1"] = 12}, {["x"] = 4, ["meta"] = {["inventory"] = {}, ["fields"] = {}}, ["y"] = 0, ["name"] = "default:water_source", ["z"] = 5, ["param1"] = 11}, {["x"] = 4, ["meta"] = {["inventory"] = {}, ["fields"] = {}}, ["y"] = 0, ["name"] = "default:water_source", ["z"] = 6, ["param1"] = 11}, {["x"] = 4, ["meta"] = {["inventory"] = {}, ["fields"] = {}}, ["y"] = 0, ["name"] = "default:water_source", ["z"] = 7, ["param1"] = 11}, {["x"] = 4, ["meta"] = {["inventory"] = {}, ["fields"] = {}}, ["y"] = 0, ["name"] = "default:water_source", ["z"] = 8, ["param1"] = 11}, {["x"] = 4, ["meta"] = {["inventory"] = {}, ["fields"] = {}}, ["y"] = 0, ["name"] = "default:water_source", ["z"] = 9, ["param1"] = 11}, {["x"] = 4, ["meta"] = {["inventory"] = {}, ["fields"] = {}}, ["y"] = 0, ["name"] = "default:water_source", ["z"] = 10, ["param1"] = 11}, {["x"] = 4, ["meta"] = {["inventory"] = {}, ["fields"] = {}}, ["y"] = 0, ["name"] = "default:water_source", ["z"] = 11, ["param1"] = 11}, {["x"] = 4, ["meta"] = {["inventory"] = {}, ["fields"] = {}}, ["y"] = 0, ["name"] = "default:water_source", ["z"] = 12, ["param1"] = 12}, {["x"] = 4, ["meta"] = {["inventory"] = {}, ["fields"] = {}}, ["y"] = 0, ["name"] = "default:water_source", ["z"] = 13, ["param1"] = 13}, {["x"] = 4, ["meta"] = {["inventory"] = {}, ["fields"] = {}}, ["y"] = 0, ["name"] = "default:water_source", ["z"] = 14, ["param1"] = 14}, {["x"] = 4, ["meta"] = {["inventory"] = {}, ["fields"] = {}}, ["y"] = 0, ["name"] = "default:water_source", ["z"] = 15, ["param1"] = 14}, {["x"] = 4, ["meta"] = {["inventory"] = {}, ["fields"] = {}}, ["y"] = 0, ["name"] = "default:water_source", ["z"] = 16, ["param1"] = 14}, {["x"] = 4, ["meta"] = {["inventory"] = {}, ["fields"] = {}}, ["param2"] = 14, ["y"] = 1, ["name"] = "building_blocks:panel_hardwood_4", ["z"] = 5, ["param1"] = 12}, {["x"] = 4, ["meta"] = {["inventory"] = {}, ["fields"] = {}}, ["param2"] = 12, ["y"] = 1, ["name"] = "building_blocks:panel_hardwood_4", ["z"] = 11, ["param1"] = 12}, {["x"] = 4, ["meta"] = {["inventory"] = {}, ["fields"] = {}}, ["param2"] = 12, ["y"] = 2, ["name"] = "building_blocks:panel_hardwood_4", ["z"] = 5, ["param1"] = 12}, {["x"] = 4, ["meta"] = {["inventory"] = {}, ["fields"] = {}}, ["param2"] = 14, ["y"] = 2, ["name"] = "building_blocks:panel_hardwood_4", ["z"] = 11, ["param1"] = 12}, {["x"] = 4, ["meta"] = {["inventory"] = {}, ["fields"] = {}}, ["param2"] = 14, ["y"] = 3, ["name"] = "building_blocks:panel_hardwood_4", ["z"] = 6, ["param1"] = 12}, {["x"] = 4, ["meta"] = {["inventory"] = {}, ["fields"] = {}}, ["param2"] = 12, ["y"] = 3, ["name"] = "building_blocks:panel_hardwood_4", ["z"] = 10, ["param1"] = 12}, {["x"] = 4, ["meta"] = {["inventory"] = {}, ["fields"] = {}}, ["param2"] = 12, ["y"] = 4, ["name"] = "building_blocks:panel_hardwood_4", ["z"] = 6, ["param1"] = 12}, {["x"] = 4, ["meta"] = {["inventory"] = {}, ["fields"] = {}}, ["param2"] = 14, ["y"] = 4, ["name"] = "building_blocks:panel_hardwood_4", ["z"] = 10, ["param1"] = 12}, {["x"] = 4, ["meta"] = {["inventory"] = {}, ["fields"] = {}}, ["param2"] = 14, ["y"] = 5, ["name"] = "building_blocks:panel_hardwood_4", ["z"] = 7, ["param1"] = 12}, {["x"] = 4, ["meta"] = {["inventory"] = {}, ["fields"] = {}}, ["param2"] = 12, ["y"] = 5, ["name"] = "building_blocks:panel_hardwood_4", ["z"] = 9, ["param1"] = 12}, {["x"] = 4, ["meta"] = {["inventory"] = {}, ["fields"] = {}}, ["param2"] = 12, ["y"] = 6, ["name"] = "building_blocks:panel_hardwood_4", ["z"] = 7, ["param1"] = 12}, {["x"] = 4, ["meta"] = {["inventory"] = {}, ["fields"] = {}}, ["param2"] = 14, ["y"] = 6, ["name"] = "building_blocks:panel_hardwood_4", ["z"] = 9, ["param1"] = 12}, {["x"] = 4, ["meta"] = {["inventory"] = {}, ["fields"] = {}}, ["param2"] = 1, ["y"] = 7, ["name"] = "default:tree", ["z"] = 5}, {["x"] = 4, ["meta"] = {["inventory"] = {}, ["fields"] = {}}, ["param2"] = 12, ["y"] = 7, ["name"] = "building_blocks:slab_hardwood_quarter", ["z"] = 8, ["param1"] = 12}, {["x"] = 4, ["meta"] = {["inventory"] = {}, ["fields"] = {}}, ["param2"] = 1, ["y"] = 8, ["name"] = "default:tree", ["z"] = 5}, {["x"] = 4, ["meta"] = {["inventory"] = {}, ["fields"] = {}}, ["param2"] = 12, ["y"] = 8, ["name"] = "building_blocks:panel_hardwood_4", ["z"] = 7, ["param1"] = 12}, {["x"] = 4, ["meta"] = {["inventory"] = {}, ["fields"] = {}}, ["param2"] = 14, ["y"] = 8, ["name"] = "building_blocks:panel_hardwood_4", ["z"] = 9, ["param1"] = 12}, {["x"] = 4, ["meta"] = {["inventory"] = {}, ["fields"] = {}}, ["param2"] = 1, ["y"] = 8, ["name"] = "default:tree", ["z"] = 11}, {["x"] = 4, ["meta"] = {["inventory"] = {}, ["fields"] = {}}, ["param2"] = 1, ["y"] = 9, ["name"] = "default:tree", ["z"] = 5}, {["x"] = 4, ["meta"] = {["inventory"] = {}, ["fields"] = {}}, ["param2"] = 14, ["y"] = 9, ["name"] = "building_blocks:panel_hardwood_4", ["z"] = 7, ["param1"] = 12}, {["x"] = 4, ["meta"] = {["inventory"] = {}, ["fields"] = {}}, ["param2"] = 12, ["y"] = 9, ["name"] = "building_blocks:panel_hardwood_4", ["z"] = 9, ["param1"] = 12}, {["x"] = 4, ["meta"] = {["inventory"] = {}, ["fields"] = {}}, ["param2"] = 1, ["y"] = 9, ["name"] = "default:tree", ["z"] = 11}, {["x"] = 4, ["meta"] = {["inventory"] = {}, ["fields"] = {}}, ["param2"] = 1, ["y"] = 10, ["name"] = "default:tree", ["z"] = 5}, {["x"] = 4, ["meta"] = {["inventory"] = {}, ["fields"] = {}}, ["param2"] = 12, ["y"] = 10, ["name"] = "building_blocks:panel_hardwood_4", ["z"] = 6, ["param1"] = 12}, {["x"] = 4, ["meta"] = {["inventory"] = {}, ["fields"] = {}}, ["param2"] = 14, ["y"] = 10, ["name"] = "building_blocks:panel_hardwood_4", ["z"] = 10, ["param1"] = 12}, {["x"] = 4, ["meta"] = {["inventory"] = {}, ["fields"] = {}}, ["param2"] = 1, ["y"] = 10, ["name"] = "default:tree", ["z"] = 11}, {["x"] = 4, ["meta"] = {["inventory"] = {}, ["fields"] = {}}, ["param2"] = 1, ["y"] = 11, ["name"] = "default:tree", ["z"] = 5}, {["x"] = 4, ["meta"] = {["inventory"] = {}, ["fields"] = {}}, ["param2"] = 14, ["y"] = 11, ["name"] = "building_blocks:panel_hardwood_4", ["z"] = 6, ["param1"] = 12}, {["x"] = 4, ["meta"] = {["inventory"] = {}, ["fields"] = {}}, ["param2"] = 12, ["y"] = 11, ["name"] = "building_blocks:panel_hardwood_4", ["z"] = 10, ["param1"] = 12}, {["x"] = 4, ["meta"] = {["inventory"] = {}, ["fields"] = {}}, ["param2"] = 1, ["y"] = 11, ["name"] = "default:tree", ["z"] = 11}, {["x"] = 4, ["meta"] = {["inventory"] = {}, ["fields"] = {}}, ["param2"] = 1, ["y"] = 12, ["name"] = "default:tree", ["z"] = 5}, {["x"] = 4, ["meta"] = {["inventory"] = {}, ["fields"] = {}}, ["param2"] = 1, ["y"] = 12, ["name"] = "default:tree", ["z"] = 11}, {["x"] = 4, ["meta"] = {["inventory"] = {}, ["fields"] = {}}, ["param2"] = 1, ["y"] = 13, ["name"] = "default:tree", ["z"] = 5}, {["x"] = 4, ["meta"] = {["inventory"] = {}, ["fields"] = {}}, ["param2"] = 1, ["y"] = 13, ["name"] = "default:tree", ["z"] = 11}, {["x"] = 4, ["meta"] = {["inventory"] = {}, ["fields"] = {}}, ["param2"] = 1, ["y"] = 14, ["name"] = "default:tree", ["z"] = 5}, {["x"] = 4, ["meta"] = {["inventory"] = {}, ["fields"] = {}}, ["param2"] = 1, ["y"] = 14, ["name"] = "default:tree", ["z"] = 11}, {["x"] = 4, ["meta"] = {["inventory"] = {}, ["fields"] = {}}, ["param2"] = 1, ["y"] = 15, ["name"] = "default:tree", ["z"] = 5}, {["x"] = 4, ["meta"] = {["inventory"] = {}, ["fields"] = {}}, ["param2"] = 1, ["y"] = 15, ["name"] = "default:tree", ["z"] = 11}, {["x"] = 4, ["meta"] = {["inventory"] = {}, ["fields"] = {}}, ["param2"] = 8, ["y"] = 16, ["name"] = "building_blocks:slope_hardwood_half_raised", ["z"] = 4, ["param1"] = 13}, {["x"] = 4, ["meta"] = {["inventory"] = {}, ["fields"] = {}}, ["param2"] = 1, ["y"] = 16, ["name"] = "default:tree", ["z"] = 5}, {["x"] = 4, ["meta"] = {["inventory"] = {}, ["fields"] = {}}, ["param2"] = 1, ["y"] = 16, ["name"] = "default:tree", ["z"] = 11}, {["x"] = 4, ["meta"] = {["inventory"] = {}, ["fields"] = {}}, ["param2"] = 6, ["y"] = 16, ["name"] = "building_blocks:slope_hardwood_half_raised", ["z"] = 12, ["param1"] = 61}, {["x"] = 4, ["meta"] = {["inventory"] = {}, ["fields"] = {}}, ["param2"] = 20, ["y"] = 17, ["name"] = "building_blocks:slope_hardwood_half_raised", ["z"] = 3, ["param1"] = 30}, {["x"] = 4, ["meta"] = {["inventory"] = {}, ["fields"] = {}}, ["y"] = 17, ["name"] = "building_blocks:hardwood", ["z"] = 4, ["param1"] = 15}, {["x"] = 4, ["meta"] = {["inventory"] = {}, ["fields"] = {}}, ["y"] = 17, ["name"] = "building_blocks:hardwood", ["z"] = 5, ["param1"] = 15}, {["x"] = 4, ["meta"] = {["inventory"] = {}, ["fields"] = {}}, ["y"] = 17, ["name"] = "building_blocks:hardwood", ["z"] = 6, ["param1"] = 15}, {["x"] = 4, ["meta"] = {["inventory"] = {}, ["fields"] = {}}, ["y"] = 17, ["name"] = "building_blocks:hardwood", ["z"] = 7, ["param1"] = 15}, {["x"] = 4, ["meta"] = {["inventory"] = {}, ["fields"] = {}}, ["y"] = 17, ["name"] = "building_blocks:hardwood", ["z"] = 8, ["param1"] = 15}, {["x"] = 4, ["meta"] = {["inventory"] = {}, ["fields"] = {}}, ["y"] = 17, ["name"] = "building_blocks:hardwood", ["z"] = 9, ["param1"] = 15}, {["x"] = 4, ["meta"] = {["inventory"] = {}, ["fields"] = {}}, ["y"] = 17, ["name"] = "building_blocks:hardwood", ["z"] = 10, ["param1"] = 15}, {["x"] = 4, ["meta"] = {["inventory"] = {}, ["fields"] = {}}, ["y"] = 17, ["name"] = "building_blocks:hardwood", ["z"] = 11, ["param1"] = 15}, {["x"] = 4, ["meta"] = {["inventory"] = {}, ["fields"] = {}}, ["y"] = 17, ["name"] = "building_blocks:hardwood", ["z"] = 12, ["param1"] = 15}, {["x"] = 4, ["meta"] = {["inventory"] = {}, ["fields"] = {}}, ["param2"] = 22, ["y"] = 17, ["name"] = "building_blocks:slope_hardwood_half_raised", ["z"] = 13, ["param1"] = 94}, {["x"] = 4, ["meta"] = {["inventory"] = {}, ["fields"] = {}}, ["y"] = 18, ["name"] = "ethereal:fence_redwood", ["z"] = 3, ["param1"] = 47}, {["x"] = 4, ["meta"] = {["inventory"] = {}, ["fields"] = {}}, ["param2"] = 1, ["y"] = 18, ["name"] = "default:tree", ["z"] = 5}, {["x"] = 4, ["meta"] = {["inventory"] = {}, ["fields"] = {["palette_index"] = "0"}}, ["param2"] = 18, ["y"] = 18, ["name"] = "moreblocks:slab_wood_tile_full", ["z"] = 6, ["param1"] = 93}, {["x"] = 4, ["meta"] = {["inventory"] = {}, ["fields"] = {["palette_index"] = "0"}}, ["param2"] = 18, ["y"] = 18, ["name"] = "moreblocks:panel_wood_tile_full", ["z"] = 7, ["param1"] = 109}, {["x"] = 4, ["meta"] = {["inventory"] = {}, ["fields"] = {}}, ["param2"] = 18, ["y"] = 18, ["name"] = "moreblocks:panel_wood_tile_full", ["z"] = 8, ["param1"] = 125}, {["x"] = 4, ["meta"] = {["inventory"] = {}, ["fields"] = {}}, ["param2"] = 18, ["y"] = 18, ["name"] = "moreblocks:slab_wood_tile_full", ["z"] = 9, ["param1"] = 141}, {["x"] = 4, ["meta"] = {["inventory"] = {}, ["fields"] = {}}, ["param2"] = 18, ["y"] = 18, ["name"] = "moreblocks:slab_wood_tile_full", ["z"] = 10, ["param1"] = 157}, {["x"] = 4, ["meta"] = {["inventory"] = {}, ["fields"] = {}}, ["param2"] = 1, ["y"] = 18, ["name"] = "default:tree", ["z"] = 11}, {["x"] = 4, ["meta"] = {["inventory"] = {}, ["fields"] = {}}, ["y"] = 18, ["name"] = "ethereal:fence_redwood", ["z"] = 13, ["param1"] = 111}, {["x"] = 4, ["meta"] = {["inventory"] = {}, ["fields"] = {}}, ["param2"] = 1, ["y"] = 19, ["name"] = "default:tree", ["z"] = 5}, {["x"] = 4, ["meta"] = {["inventory"] = {}, ["fields"] = {}}, ["param2"] = 18, ["y"] = 19, ["name"] = "moreblocks:panel_wood_tile_full", ["z"] = 6, ["param1"] = 77}, {["x"] = 4, ["meta"] = {["inventory"] = {}, ["fields"] = {}}, ["param2"] = 18, ["y"] = 19, ["name"] = "moreblocks:panel_wood_tile_full", ["z"] = 7, ["param1"] = 93}, {["x"] = 4, ["meta"] = {["inventory"] = {}, ["fields"] = {}}, ["param2"] = 18, ["y"] = 19, ["name"] = "moreblocks:slab_wood_tile_full", ["z"] = 8, ["param1"] = 109}, {["x"] = 4, ["meta"] = {["inventory"] = {}, ["fields"] = {}}, ["param2"] = 18, ["y"] = 19, ["name"] = "moreblocks:panel_wood_tile_full", ["z"] = 9, ["param1"] = 125}, {["x"] = 4, ["meta"] = {["inventory"] = {}, ["fields"] = {}}, ["param2"] = 18, ["y"] = 19, ["name"] = "moreblocks:slab_wood_tile_full", ["z"] = 10, ["param1"] = 141}, {["x"] = 4, ["meta"] = {["inventory"] = {}, ["fields"] = {}}, ["param2"] = 1, ["y"] = 19, ["name"] = "default:tree", ["z"] = 11}, {["x"] = 4, ["meta"] = {["inventory"] = {}, ["fields"] = {}}, ["param2"] = 1, ["y"] = 20, ["name"] = "default:tree", ["z"] = 5}, {["x"] = 4, ["meta"] = {["inventory"] = {}, ["fields"] = {}}, ["param2"] = 18, ["y"] = 20, ["name"] = "moreblocks:panel_wood_tile_full", ["z"] = 6, ["param1"] = 61}, {["x"] = 4, ["meta"] = {["inventory"] = {}, ["fields"] = {}}, ["param2"] = 18, ["y"] = 20, ["name"] = "moreblocks:slab_wood_tile_full", ["z"] = 7, ["param1"] = 77}, {["x"] = 4, ["meta"] = {["inventory"] = {}, ["fields"] = {}}, ["param2"] = 18, ["y"] = 20, ["name"] = "moreblocks:slab_wood_tile_full", ["z"] = 8, ["param1"] = 93}, {["x"] = 4, ["meta"] = {["inventory"] = {}, ["fields"] = {}}, ["param2"] = 18, ["y"] = 20, ["name"] = "moreblocks:panel_wood_tile_full", ["z"] = 9, ["param1"] = 109}, {["x"] = 4, ["meta"] = {["inventory"] = {}, ["fields"] = {}}, ["param2"] = 18, ["y"] = 20, ["name"] = "moreblocks:slab_wood_tile_full", ["z"] = 10, ["param1"] = 125}, {["x"] = 4, ["meta"] = {["inventory"] = {}, ["fields"] = {}}, ["param2"] = 1, ["y"] = 20, ["name"] = "default:tree", ["z"] = 11}, {["x"] = 4, ["meta"] = {["inventory"] = {}, ["fields"] = {}}, ["y"] = 21, ["name"] = "moreblocks:slope_copperpatina_half", ["z"] = 4, ["param1"] = 14}, {["x"] = 4, ["meta"] = {["inventory"] = {}, ["fields"] = {}}, ["param2"] = 1, ["y"] = 21, ["name"] = "moreblocks:slope_copperpatina_outer_half_raised", ["z"] = 5, ["param1"] = 30}, {["x"] = 4, ["meta"] = {["inventory"] = {}, ["fields"] = {}}, ["param2"] = 1, ["y"] = 21, ["name"] = "moreblocks:slope_copperpatina_half_raised", ["z"] = 6, ["param1"] = 46}, {["x"] = 4, ["meta"] = {["inventory"] = {}, ["fields"] = {}}, ["param2"] = 1, ["y"] = 21, ["name"] = "moreblocks:slope_copperpatina_half_raised", ["z"] = 7, ["param1"] = 62}, {["x"] = 4, ["meta"] = {["inventory"] = {}, ["fields"] = {}}, ["param2"] = 1, ["y"] = 21, ["name"] = "moreblocks:slope_copperpatina_half_raised", ["z"] = 8, ["param1"] = 78}, {["x"] = 4, ["meta"] = {["inventory"] = {}, ["fields"] = {}}, ["param2"] = 1, ["y"] = 21, ["name"] = "moreblocks:slope_copperpatina_half_raised", ["z"] = 9, ["param1"] = 94}, {["x"] = 4, ["meta"] = {["inventory"] = {}, ["fields"] = {}}, ["param2"] = 1, ["y"] = 21, ["name"] = "moreblocks:slope_copperpatina_half_raised", ["z"] = 10, ["param1"] = 110}, {["x"] = 4, ["meta"] = {["inventory"] = {}, ["fields"] = {}}, ["param2"] = 2, ["y"] = 21, ["name"] = "moreblocks:slope_copperpatina_outer_half_raised", ["z"] = 11, ["param1"] = 94}, {["x"] = 4, ["meta"] = {["inventory"] = {}, ["fields"] = {}}, ["param2"] = 2, ["y"] = 21, ["name"] = "moreblocks:slope_copperpatina_half", ["z"] = 12, ["param1"] = 78}, {["x"] = 5, ["meta"] = {["inventory"] = {}, ["fields"] = {}}, ["y"] = 0, ["name"] = "default:water_source", ["z"] = 0, ["param1"] = 14}, {["x"] = 5, ["meta"] = {["inventory"] = {}, ["fields"] = {}}, ["y"] = 0, ["name"] = "default:water_source", ["z"] = 1, ["param1"] = 14}, {["x"] = 5, ["meta"] = {["inventory"] = {}, ["fields"] = {}}, ["y"] = 0, ["name"] = "default:water_source", ["z"] = 2, ["param1"] = 14}, {["x"] = 5, ["meta"] = {["inventory"] = {}, ["fields"] = {}}, ["y"] = 0, ["name"] = "default:water_source", ["z"] = 3, ["param1"] = 13}, {["x"] = 5, ["meta"] = {["inventory"] = {}, ["fields"] = {}}, ["param2"] = 240, ["y"] = 0, ["name"] = "default:water_source", ["z"] = 4, ["param1"] = 12}, {["x"] = 5, ["meta"] = {["inventory"] = {}, ["fields"] = {}}, ["param2"] = 240, ["y"] = 0, ["name"] = "default:water_source", ["z"] = 5, ["param1"] = 11}, {["x"] = 5, ["meta"] = {["inventory"] = {}, ["fields"] = {}}, ["param2"] = 240, ["y"] = 0, ["name"] = "default:water_source", ["z"] = 6, ["param1"] = 10}, {["x"] = 5, ["meta"] = {["inventory"] = {}, ["fields"] = {}}, ["param2"] = 240, ["y"] = 0, ["name"] = "default:water_source", ["z"] = 7, ["param1"] = 10}, {["x"] = 5, ["meta"] = {["inventory"] = {}, ["fields"] = {}}, ["param2"] = 240, ["y"] = 0, ["name"] = "default:water_source", ["z"] = 8, ["param1"] = 10}, {["x"] = 5, ["meta"] = {["inventory"] = {}, ["fields"] = {}}, ["param2"] = 240, ["y"] = 0, ["name"] = "default:water_source", ["z"] = 9, ["param1"] = 10}, {["x"] = 5, ["meta"] = {["inventory"] = {}, ["fields"] = {}}, ["param2"] = 240, ["y"] = 0, ["name"] = "default:water_source", ["z"] = 10, ["param1"] = 10}, {["x"] = 5, ["meta"] = {["inventory"] = {}, ["fields"] = {}}, ["param2"] = 240, ["y"] = 0, ["name"] = "default:water_source", ["z"] = 11, ["param1"] = 11}, {["x"] = 5, ["meta"] = {["inventory"] = {}, ["fields"] = {}}, ["param2"] = 240, ["y"] = 0, ["name"] = "default:water_source", ["z"] = 12, ["param1"] = 12}, {["x"] = 5, ["meta"] = {["inventory"] = {}, ["fields"] = {}}, ["y"] = 0, ["name"] = "default:water_source", ["z"] = 13, ["param1"] = 13}, {["x"] = 5, ["meta"] = {["inventory"] = {}, ["fields"] = {}}, ["y"] = 0, ["name"] = "default:water_source", ["z"] = 14, ["param1"] = 14}, {["x"] = 5, ["meta"] = {["inventory"] = {}, ["fields"] = {}}, ["y"] = 0, ["name"] = "default:water_source", ["z"] = 15, ["param1"] = 14}, {["x"] = 5, ["meta"] = {["inventory"] = {}, ["fields"] = {}}, ["y"] = 0, ["name"] = "default:water_source", ["z"] = 16, ["param1"] = 14}, {["x"] = 5, ["meta"] = {["inventory"] = {}, ["fields"] = {}}, ["param2"] = 21, ["y"] = 1, ["name"] = "moreblocks:slab_wood_tile_full", ["z"] = 5, ["param1"] = 12}, {["x"] = 5, ["meta"] = {["inventory"] = {}, ["fields"] = {}}, ["param2"] = 21, ["y"] = 1, ["name"] = "moreblocks:slab_wood_tile_full", ["z"] = 6, ["param1"] = 11}, {["x"] = 5, ["meta"] = {["inventory"] = {}, ["fields"] = {}}, ["param2"] = 21, ["y"] = 1, ["name"] = "moreblocks:slab_wood_tile_full", ["z"] = 7, ["param1"] = 11}, {["x"] = 5, ["meta"] = {["inventory"] = {}, ["fields"] = {}}, ["param2"] = 21, ["y"] = 1, ["name"] = "moreblocks:slab_wood_tile_full", ["z"] = 8, ["param1"] = 11}, {["x"] = 5, ["meta"] = {["inventory"] = {}, ["fields"] = {}}, ["param2"] = 21, ["y"] = 1, ["name"] = "moreblocks:slab_wood_tile_full", ["z"] = 9, ["param1"] = 11}, {["x"] = 5, ["meta"] = {["inventory"] = {}, ["fields"] = {}}, ["param2"] = 21, ["y"] = 1, ["name"] = "moreblocks:slab_wood_tile_full", ["z"] = 10, ["param1"] = 11}, {["x"] = 5, ["meta"] = {["inventory"] = {}, ["fields"] = {}}, ["param2"] = 21, ["y"] = 1, ["name"] = "moreblocks:slab_wood_tile_full", ["z"] = 11, ["param1"] = 12}, {["x"] = 5, ["meta"] = {["inventory"] = {}, ["fields"] = {["length_remaining"] = "47", ["placer"] = "Antares1"}}, ["y"] = 2, ["name"] = "ropes:rope_bottom", ["z"] = 6, ["param1"] = 11}, {["x"] = 5, ["meta"] = {["inventory"] = {}, ["fields"] = {["length_remaining"] = "47", ["placer"] = "Antares1"}}, ["y"] = 2, ["name"] = "ropes:rope_bottom", ["z"] = 10, ["param1"] = 11}, {["x"] = 5, ["meta"] = {["inventory"] = {}, ["fields"] = {}}, ["y"] = 3, ["name"] = "ropes:rope", ["z"] = 6, ["param1"] = 11}, {["x"] = 5, ["meta"] = {["inventory"] = {}, ["fields"] = {}}, ["y"] = 3, ["name"] = "ropes:rope", ["z"] = 10, ["param1"] = 11}, {["x"] = 5, ["meta"] = {["inventory"] = {}, ["fields"] = {}}, ["y"] = 4, ["name"] = "ropes:rope", ["z"] = 6, ["param1"] = 11}, {["x"] = 5, ["meta"] = {["inventory"] = {}, ["fields"] = {}}, ["y"] = 4, ["name"] = "ropes:rope", ["z"] = 10, ["param1"] = 11}, {["x"] = 5, ["meta"] = {["inventory"] = {}, ["fields"] = {}}, ["y"] = 5, ["name"] = "ropes:rope", ["z"] = 6, ["param1"] = 11}, {["x"] = 5, ["meta"] = {["inventory"] = {}, ["fields"] = {}}, ["y"] = 5, ["name"] = "ropes:rope", ["z"] = 10, ["param1"] = 11}, {["x"] = 5, ["meta"] = {["inventory"] = {}, ["fields"] = {}}, ["y"] = 6, ["name"] = "ropes:wood1rope_block", ["z"] = 6, ["param1"] = 11}, {["x"] = 5, ["meta"] = {["inventory"] = {}, ["fields"] = {}}, ["y"] = 6, ["name"] = "ropes:wood1rope_block", ["z"] = 10, ["param1"] = 11}, {["x"] = 5, ["meta"] = {["inventory"] = {}, ["fields"] = {}}, ["y"] = 7, ["name"] = "moreblocks:wood_tile_full", ["z"] = 6}, {["x"] = 5, ["meta"] = {["inventory"] = {}, ["fields"] = {}}, ["param2"] = 21, ["y"] = 7, ["name"] = "moreblocks:slab_wood_tile_full", ["z"] = 7, ["param1"] = 11}, {["x"] = 5, ["meta"] = {["inventory"] = {}, ["fields"] = {}}, ["param2"] = 21, ["y"] = 7, ["name"] = "moreblocks:slab_wood_tile_full", ["z"] = 8, ["param1"] = 11}, {["x"] = 5, ["meta"] = {["inventory"] = {}, ["fields"] = {}}, ["param2"] = 21, ["y"] = 7, ["name"] = "moreblocks:slab_wood_tile_full", ["z"] = 9, ["param1"] = 11}, {["x"] = 5, ["meta"] = {["inventory"] = {}, ["fields"] = {}}, ["y"] = 7, ["name"] = "moreblocks:wood_tile_full", ["z"] = 10}, {["x"] = 5, ["meta"] = {["inventory"] = {}, ["fields"] = {["placer"] = "Antares1", ["length_remaining"] = "49"}}, ["y"] = 8, ["name"] = "ropes:rope_bottom", ["z"] = 6, ["param1"] = 11}, {["x"] = 5, ["meta"] = {["inventory"] = {}, ["fields"] = {["placer"] = "Antares1", ["length_remaining"] = "49"}}, ["y"] = 8, ["name"] = "ropes:rope_bottom", ["z"] = 10, ["param1"] = 11}, {["x"] = 5, ["meta"] = {["inventory"] = {}, ["fields"] = {}}, ["y"] = 9, ["name"] = "ropes:rope", ["z"] = 6, ["param1"] = 11}, {["x"] = 5, ["meta"] = {["inventory"] = {}, ["fields"] = {}}, ["y"] = 9, ["name"] = "ropes:rope", ["z"] = 10, ["param1"] = 11}, {["x"] = 5, ["meta"] = {["inventory"] = {}, ["fields"] = {}}, ["y"] = 10, ["name"] = "ropes:wood1rope_block", ["z"] = 6, ["param1"] = 11}, {["x"] = 5, ["meta"] = {["inventory"] = {}, ["fields"] = {}}, ["y"] = 10, ["name"] = "ropes:wood1rope_block", ["z"] = 10, ["param1"] = 11}, {["x"] = 5, ["meta"] = {["inventory"] = {}, ["fields"] = {}}, ["y"] = 11, ["name"] = "moreblocks:wood_tile_full", ["z"] = 6}, {["x"] = 5, ["meta"] = {["inventory"] = {}, ["fields"] = {}}, ["param2"] = 21, ["y"] = 11, ["name"] = "moreblocks:slab_wood_tile_full", ["z"] = 7, ["param1"] = 11}, {["x"] = 5, ["meta"] = {["inventory"] = {}, ["fields"] = {}}, ["param2"] = 21, ["y"] = 11, ["name"] = "moreblocks:slab_wood_tile_full", ["z"] = 8, ["param1"] = 11}, {["x"] = 5, ["meta"] = {["inventory"] = {}, ["fields"] = {}}, ["param2"] = 21, ["y"] = 11, ["name"] = "moreblocks:slab_wood_tile_full", ["z"] = 9, ["param1"] = 11}, {["x"] = 5, ["meta"] = {["inventory"] = {}, ["fields"] = {}}, ["y"] = 11, ["name"] = "moreblocks:wood_tile_full", ["z"] = 10}, {["x"] = 5, ["meta"] = {["inventory"] = {}, ["fields"] = {["placer"] = "Antares1", ["length_remaining"] = "47"}}, ["y"] = 12, ["name"] = "ropes:rope_bottom", ["z"] = 6, ["param1"] = 11}, {["x"] = 5, ["meta"] = {["inventory"] = {}, ["fields"] = {["placer"] = "Antares1", ["length_remaining"] = "47"}}, ["y"] = 12, ["name"] = "ropes:rope_bottom", ["z"] = 10, ["param1"] = 11}, {["x"] = 5, ["meta"] = {["inventory"] = {}, ["fields"] = {}}, ["y"] = 13, ["name"] = "ropes:rope", ["z"] = 6, ["param1"] = 11}, {["x"] = 5, ["meta"] = {["inventory"] = {}, ["fields"] = {}}, ["y"] = 13, ["name"] = "ropes:rope", ["z"] = 10, ["param1"] = 11}, {["x"] = 5, ["meta"] = {["inventory"] = {}, ["fields"] = {}}, ["y"] = 14, ["name"] = "ropes:rope", ["z"] = 6, ["param1"] = 11}, {["x"] = 5, ["meta"] = {["inventory"] = {}, ["fields"] = {}}, ["y"] = 14, ["name"] = "ropes:rope", ["z"] = 10, ["param1"] = 11}, {["x"] = 5, ["meta"] = {["inventory"] = {}, ["fields"] = {}}, ["y"] = 15, ["name"] = "ropes:rope", ["z"] = 6, ["param1"] = 27}, {["x"] = 5, ["meta"] = {["inventory"] = {}, ["fields"] = {}}, ["y"] = 15, ["name"] = "ropes:rope", ["z"] = 10, ["param1"] = 27}, {["x"] = 5, ["meta"] = {["inventory"] = {}, ["fields"] = {}}, ["param2"] = 8, ["y"] = 16, ["name"] = "building_blocks:slope_hardwood_half_raised", ["z"] = 4, ["param1"] = 13}, {["x"] = 5, ["meta"] = {["inventory"] = {}, ["fields"] = {}}, ["y"] = 16, ["name"] = "ropes:wood1rope_block", ["z"] = 6, ["param1"] = 43}, {["x"] = 5, ["meta"] = {["inventory"] = {}, ["fields"] = {}}, ["y"] = 16, ["name"] = "ropes:wood1rope_block", ["z"] = 10, ["param1"] = 43}, {["x"] = 5, ["meta"] = {["inventory"] = {}, ["fields"] = {}}, ["param2"] = 6, ["y"] = 16, ["name"] = "building_blocks:slope_hardwood_half_raised", ["z"] = 12, ["param1"] = 77}, {["x"] = 5, ["meta"] = {["inventory"] = {}, ["fields"] = {}}, ["param2"] = 20, ["y"] = 17, ["name"] = "building_blocks:slope_hardwood_half_raised", ["z"] = 3, ["param1"] = 46}, {["x"] = 5, ["meta"] = {["inventory"] = {}, ["fields"] = {}}, ["y"] = 17, ["name"] = "building_blocks:hardwood", ["z"] = 4, ["param1"] = 14}, {["x"] = 5, ["meta"] = {["inventory"] = {}, ["fields"] = {}}, ["y"] = 17, ["name"] = "building_blocks:hardwood", ["z"] = 5, ["param1"] = 15}, {["x"] = 5, ["meta"] = {["inventory"] = {}, ["fields"] = {}}, ["y"] = 17, ["name"] = "building_blocks:hardwood", ["z"] = 6, ["param1"] = 15}, {["x"] = 5, ["meta"] = {["inventory"] = {}, ["fields"] = {}}, ["y"] = 17, ["name"] = "building_blocks:hardwood", ["z"] = 7, ["param1"] = 15}, {["x"] = 5, ["meta"] = {["inventory"] = {}, ["fields"] = {}}, ["y"] = 17, ["name"] = "building_blocks:hardwood", ["z"] = 8, ["param1"] = 15}, {["x"] = 5, ["meta"] = {["inventory"] = {}, ["fields"] = {}}, ["y"] = 17, ["name"] = "building_blocks:hardwood", ["z"] = 9, ["param1"] = 15}, {["x"] = 5, ["meta"] = {["inventory"] = {}, ["fields"] = {}}, ["y"] = 17, ["name"] = "building_blocks:hardwood", ["z"] = 10, ["param1"] = 15}, {["x"] = 5, ["meta"] = {["inventory"] = {}, ["fields"] = {}}, ["y"] = 17, ["name"] = "building_blocks:hardwood", ["z"] = 11, ["param1"] = 15}, {["x"] = 5, ["meta"] = {["inventory"] = {}, ["fields"] = {}}, ["y"] = 17, ["name"] = "building_blocks:hardwood", ["z"] = 12, ["param1"] = 15}, {["x"] = 5, ["meta"] = {["inventory"] = {}, ["fields"] = {}}, ["param2"] = 22, ["y"] = 17, ["name"] = "building_blocks:slope_hardwood_half_raised", ["z"] = 13, ["param1"] = 110}, {["x"] = 5, ["meta"] = {["inventory"] = {}, ["fields"] = {}}, ["y"] = 18, ["name"] = "ethereal:fence_redwood", ["z"] = 3, ["param1"] = 63}, {["x"] = 5, ["meta"] = {["inventory"] = {}, ["fields"] = {}}, ["param2"] = 9, ["y"] = 18, ["name"] = "moreblocks:slab_wood_tile_full", ["z"] = 5, ["param1"] = 93}, {["x"] = 5, ["meta"] = {["inventory"] = {}, ["fields"] = {}}, ["param2"] = 12, ["y"] = 18, ["name"] = "moreblocks:slab_coal_glass_1", ["z"] = 7, ["param1"] = 124}, {["x"] = 5, ["meta"] = {["inventory"] = {}, ["fields"] = {}}, ["param2"] = 12, ["y"] = 18, ["name"] = "moreblocks:slab_coal_glass_1", ["z"] = 8, ["param1"] = 140}, {["x"] = 5, ["meta"] = {["inventory"] = {}, ["fields"] = {["timestamp"] = "1582050084", ["station_network"] = "Building.net", ["formspec"] = "size[12,10]label[3.3,0.0;Travelnet-Box:]label[6.3,0.0;Punch box to update target list.]label[0.3,0.4;Name of this station:]label[6.3,0.4;Black See]label[0.3,0.8;Assigned to Network:]label[6.3,0.8;Building.net]label[0.3,1.2;Owned by:]label[6.3,1.2;tomraceror]label[3.3,1.6;Click on target to travel there:]button_exit[0,2.5;4,0.5;target;Private drive]button_exit[0,3.5;4,0.5;target;Conversion-center]button_exit[0,4.5;4,0.5;target;Arena]button_exit[0,5.5;4,0.5;target;Spawn]button_exit[0,6.5;4,0.5;target;Statue of Liberty]button_exit[0,7.5;4,0.5;target;Uranium Museum]button_exit[0,8.5;4,0.5;target;Casino]button_exit[0,9.5;4,0.5;target;Pyramide]button_exit[4,2.5;4,0.5;target;Travelnet-Hub]button_exit[4,3.5;4,0.5;target;Clock tower]button_exit[4,4.5;4,0.5;target;Cen City]button_exit[4,5.5;4,0.5;target;Project MTG]button_exit[4,6.5;1,0.5;open_door;<>]label[4.9,6.35;Black See]", ["infotext"] = "Station 'Black See' on travelnet 'Building.net' (owned by tomraceror) ready for usage. Right-click to travel, punch to update.", ["owner"] = "tomraceror", ["station_name"] = "Black See"}}, ["param2"] = 3, ["y"] = 18, ["name"] = "travelnet:travelnet", ["z"] = 10, ["param1"] = 172}, {["x"] = 5, ["meta"] = {["inventory"] = {}, ["fields"] = {}}, ["param2"] = 4, ["y"] = 18, ["name"] = "moreblocks:slab_wood_tile_full", ["z"] = 11, ["param1"] = 157}, {["x"] = 5, ["meta"] = {["inventory"] = {}, ["fields"] = {}}, ["y"] = 18, ["name"] = "ethereal:fence_redwood", ["z"] = 13, ["param1"] = 127}, {["x"] = 5, ["meta"] = {["inventory"] = {}, ["fields"] = {}}, ["param2"] = 9, ["y"] = 19, ["name"] = "moreblocks:panel_wood_tile_full", ["z"] = 5, ["param1"] = 77}, {["x"] = 5, ["meta"] = {["inventory"] = {}, ["fields"] = {}}, ["y"] = 19, ["name"] = "moreblocks:coal_glass", ["z"] = 6, ["param1"] = 92}, {["x"] = 5, ["meta"] = {["inventory"] = {}, ["fields"] = {}}, ["param2"] = 12, ["y"] = 19, ["name"] = "moreblocks:slab_coal_glass_1", ["z"] = 7, ["param1"] = 108}, {["x"] = 5, ["meta"] = {["inventory"] = {}, ["fields"] = {}}, ["param2"] = 12, ["y"] = 19, ["name"] = "moreblocks:slab_coal_glass_1", ["z"] = 9, ["param1"] = 140}, {["x"] = 5, ["meta"] = {["inventory"] = {}, ["fields"] = {}}, ["param2"] = 4, ["y"] = 19, ["name"] = "moreblocks:slab_wood_tile_full", ["z"] = 11, ["param1"] = 141}, {["x"] = 5, ["meta"] = {["inventory"] = {}, ["fields"] = {}}, ["param2"] = 9, ["y"] = 20, ["name"] = "moreblocks:panel_wood_tile_full", ["z"] = 5, ["param1"] = 61}, {["x"] = 5, ["meta"] = {["inventory"] = {}, ["fields"] = {}}, ["y"] = 20, ["name"] = "moreblocks:coal_glass", ["z"] = 6, ["param1"] = 76}, {["x"] = 5, ["meta"] = {["inventory"] = {}, ["fields"] = {}}, ["param2"] = 12, ["y"] = 20, ["name"] = "moreblocks:slab_coal_glass_1", ["z"] = 9, ["param1"] = 124}, {["x"] = 5, ["meta"] = {["inventory"] = {}, ["fields"] = {}}, ["param2"] = 4, ["y"] = 20, ["name"] = "moreblocks:slab_wood_tile_full", ["z"] = 11, ["param1"] = 125}, {["x"] = 5, ["meta"] = {["inventory"] = {}, ["fields"] = {}}, ["y"] = 21, ["name"] = "moreblocks:slope_copperpatina_half", ["z"] = 4, ["param1"] = 30}, {["x"] = 5, ["meta"] = {["inventory"] = {}, ["fields"] = {}}, ["y"] = 21, ["name"] = "moreblocks:slope_copperpatina_half_raised", ["z"] = 5, ["param1"] = 46}, {["x"] = 5, ["meta"] = {["inventory"] = {}, ["fields"] = {}}, ["y"] = 21, ["name"] = "moreblocks:copperpatina", ["z"] = 6}, {["x"] = 5, ["meta"] = {["inventory"] = {}, ["fields"] = {}}, ["y"] = 21, ["name"] = "moreblocks:copperpatina", ["z"] = 7}, {["x"] = 5, ["meta"] = {["inventory"] = {}, ["fields"] = {}}, ["y"] = 21, ["name"] = "moreblocks:copperpatina", ["z"] = 8}, {["x"] = 5, ["meta"] = {["inventory"] = {}, ["fields"] = {}}, ["y"] = 21, ["name"] = "moreblocks:copperpatina", ["z"] = 9}, {["x"] = 5, ["meta"] = {["inventory"] = {}, ["fields"] = {}}, ["y"] = 21, ["name"] = "moreblocks:copperpatina", ["z"] = 10}, {["x"] = 5, ["meta"] = {["inventory"] = {}, ["fields"] = {}}, ["param2"] = 2, ["y"] = 21, ["name"] = "moreblocks:slope_copperpatina_half_raised", ["z"] = 11, ["param1"] = 110}, {["x"] = 5, ["meta"] = {["inventory"] = {}, ["fields"] = {}}, ["param2"] = 2, ["y"] = 21, ["name"] = "moreblocks:slope_copperpatina_half", ["z"] = 12, ["param1"] = 94}, {["x"] = 5, ["meta"] = {["inventory"] = {}, ["fields"] = {}}, ["param2"] = 1, ["y"] = 22, ["name"] = "moreblocks:slope_copperpatina_outer", ["z"] = 6, ["param1"] = 14}, {["x"] = 5, ["meta"] = {["inventory"] = {}, ["fields"] = {}}, ["param2"] = 1, ["y"] = 22, ["name"] = "moreblocks:slope_copperpatina", ["z"] = 7, ["param1"] = 30}, {["x"] = 5, ["meta"] = {["inventory"] = {}, ["fields"] = {}}, ["param2"] = 1, ["y"] = 22, ["name"] = "moreblocks:slope_copperpatina", ["z"] = 8, ["param1"] = 46}, {["x"] = 5, ["meta"] = {["inventory"] = {}, ["fields"] = {}}, ["param2"] = 1, ["y"] = 22, ["name"] = "moreblocks:slope_copperpatina", ["z"] = 9, ["param1"] = 62}, {["x"] = 5, ["meta"] = {["inventory"] = {}, ["fields"] = {}}, ["param2"] = 2, ["y"] = 22, ["name"] = "moreblocks:slope_copperpatina_outer", ["z"] = 10, ["param1"] = 78}, {["x"] = 6, ["meta"] = {["inventory"] = {}, ["fields"] = {}}, ["y"] = 0, ["name"] = "default:water_source", ["z"] = 0, ["param1"] = 14}, {["x"] = 6, ["meta"] = {["inventory"] = {}, ["fields"] = {}}, ["y"] = 0, ["name"] = "default:water_source", ["z"] = 1, ["param1"] = 14}, {["x"] = 6, ["meta"] = {["inventory"] = {}, ["fields"] = {}}, ["y"] = 0, ["name"] = "default:water_source", ["z"] = 2, ["param1"] = 14}, {["x"] = 6, ["meta"] = {["inventory"] = {}, ["fields"] = {}}, ["y"] = 0, ["name"] = "default:water_source", ["z"] = 3, ["param1"] = 13}, {["x"] = 6, ["meta"] = {["inventory"] = {}, ["fields"] = {}}, ["param2"] = 240, ["y"] = 0, ["name"] = "default:water_source", ["z"] = 4, ["param1"] = 12}, {["x"] = 6, ["meta"] = {["inventory"] = {}, ["fields"] = {}}, ["param2"] = 240, ["y"] = 0, ["name"] = "default:water_source", ["z"] = 5, ["param1"] = 11}, {["x"] = 6, ["meta"] = {["inventory"] = {}, ["fields"] = {}}, ["param2"] = 240, ["y"] = 0, ["name"] = "default:water_source", ["z"] = 6, ["param1"] = 10}, {["x"] = 6, ["meta"] = {["inventory"] = {}, ["fields"] = {}}, ["param2"] = 240, ["y"] = 0, ["name"] = "default:water_source", ["z"] = 7, ["param1"] = 9}, {["x"] = 6, ["meta"] = {["inventory"] = {}, ["fields"] = {}}, ["param2"] = 240, ["y"] = 0, ["name"] = "default:water_source", ["z"] = 8, ["param1"] = 9}, {["x"] = 6, ["meta"] = {["inventory"] = {}, ["fields"] = {}}, ["param2"] = 240, ["y"] = 0, ["name"] = "default:water_source", ["z"] = 9, ["param1"] = 9}, {["x"] = 6, ["meta"] = {["inventory"] = {}, ["fields"] = {}}, ["param2"] = 240, ["y"] = 0, ["name"] = "default:water_source", ["z"] = 10, ["param1"] = 10}, {["x"] = 6, ["meta"] = {["inventory"] = {}, ["fields"] = {}}, ["param2"] = 240, ["y"] = 0, ["name"] = "default:water_source", ["z"] = 11, ["param1"] = 11}, {["x"] = 6, ["meta"] = {["inventory"] = {}, ["fields"] = {}}, ["param2"] = 240, ["y"] = 0, ["name"] = "default:water_source", ["z"] = 12, ["param1"] = 12}, {["x"] = 6, ["meta"] = {["inventory"] = {}, ["fields"] = {}}, ["y"] = 0, ["name"] = "default:water_source", ["z"] = 13, ["param1"] = 13}, {["x"] = 6, ["meta"] = {["inventory"] = {}, ["fields"] = {}}, ["y"] = 0, ["name"] = "default:water_source", ["z"] = 14, ["param1"] = 14}, {["x"] = 6, ["meta"] = {["inventory"] = {}, ["fields"] = {}}, ["y"] = 0, ["name"] = "default:water_source", ["z"] = 15, ["param1"] = 14}, {["x"] = 6, ["meta"] = {["inventory"] = {}, ["fields"] = {}}, ["y"] = 0, ["name"] = "default:water_source", ["z"] = 16, ["param1"] = 14}, {["x"] = 6, ["meta"] = {["inventory"] = {}, ["fields"] = {}}, ["param2"] = 21, ["y"] = 1, ["name"] = "moreblocks:slab_wood_tile_full", ["z"] = 5, ["param1"] = 12}, {["x"] = 6, ["meta"] = {["inventory"] = {}, ["fields"] = {}}, ["param2"] = 21, ["y"] = 1, ["name"] = "moreblocks:slab_wood_tile_full", ["z"] = 6, ["param1"] = 11}, {["x"] = 6, ["meta"] = {["inventory"] = {}, ["fields"] = {}}, ["param2"] = 21, ["y"] = 1, ["name"] = "moreblocks:slab_wood_tile_full", ["z"] = 7, ["param1"] = 10}, {["x"] = 6, ["meta"] = {["inventory"] = {}, ["fields"] = {}}, ["param2"] = 21, ["y"] = 1, ["name"] = "moreblocks:slab_wood_tile_full", ["z"] = 8, ["param1"] = 10}, {["x"] = 6, ["meta"] = {["inventory"] = {}, ["fields"] = {}}, ["param2"] = 21, ["y"] = 1, ["name"] = "moreblocks:slab_wood_tile_full", ["z"] = 9, ["param1"] = 10}, {["x"] = 6, ["meta"] = {["inventory"] = {}, ["fields"] = {}}, ["param2"] = 21, ["y"] = 1, ["name"] = "moreblocks:slab_wood_tile_full", ["z"] = 10, ["param1"] = 11}, {["x"] = 6, ["meta"] = {["inventory"] = {}, ["fields"] = {}}, ["param2"] = 21, ["y"] = 1, ["name"] = "moreblocks:slab_wood_tile_full", ["z"] = 11, ["param1"] = 12}, {["x"] = 6, ["meta"] = {["inventory"] = {}, ["fields"] = {}}, ["param2"] = 21, ["y"] = 7, ["name"] = "moreblocks:slab_wood_tile_full", ["z"] = 6, ["param1"] = 11}, {["x"] = 6, ["meta"] = {["inventory"] = {}, ["fields"] = {}}, ["param2"] = 21, ["y"] = 7, ["name"] = "moreblocks:slab_wood_tile_full", ["z"] = 7, ["param1"] = 10}, {["x"] = 6, ["meta"] = {["inventory"] = {}, ["fields"] = {}}, ["param2"] = 21, ["y"] = 7, ["name"] = "moreblocks:slab_wood_tile_full", ["z"] = 9, ["param1"] = 10}, {["x"] = 6, ["meta"] = {["inventory"] = {}, ["fields"] = {}}, ["param2"] = 21, ["y"] = 7, ["name"] = "moreblocks:slab_wood_tile_full", ["z"] = 10, ["param1"] = 11}, {["x"] = 6, ["meta"] = {["inventory"] = {}, ["fields"] = {}}, ["param2"] = 21, ["y"] = 11, ["name"] = "moreblocks:slab_wood_tile_full", ["z"] = 6, ["param1"] = 11}, {["x"] = 6, ["meta"] = {["inventory"] = {}, ["fields"] = {}}, ["param2"] = 21, ["y"] = 11, ["name"] = "moreblocks:slab_wood_tile_full", ["z"] = 7, ["param1"] = 10}, {["x"] = 6, ["meta"] = {["inventory"] = {}, ["fields"] = {}}, ["param2"] = 21, ["y"] = 11, ["name"] = "moreblocks:slab_wood_tile_full", ["z"] = 9, ["param1"] = 10}, {["x"] = 6, ["meta"] = {["inventory"] = {}, ["fields"] = {}}, ["param2"] = 21, ["y"] = 11, ["name"] = "moreblocks:slab_wood_tile_full", ["z"] = 10, ["param1"] = 11}, {["x"] = 6, ["meta"] = {["inventory"] = {}, ["fields"] = {}}, ["param2"] = 8, ["y"] = 16, ["name"] = "building_blocks:slope_hardwood_half_raised", ["z"] = 4, ["param1"] = 29}, {["x"] = 6, ["meta"] = {["inventory"] = {}, ["fields"] = {}}, ["param2"] = 6, ["y"] = 16, ["name"] = "building_blocks:slope_hardwood_half_raised", ["z"] = 12, ["param1"] = 61}, {["x"] = 6, ["meta"] = {["inventory"] = {}, ["fields"] = {}}, ["param2"] = 20, ["y"] = 17, ["name"] = "building_blocks:slope_hardwood_half_raised", ["z"] = 3, ["param1"] = 30}, {["x"] = 6, ["meta"] = {["inventory"] = {}, ["fields"] = {}}, ["y"] = 17, ["name"] = "building_blocks:hardwood", ["z"] = 4, ["param1"] = 14}, {["x"] = 6, ["meta"] = {["inventory"] = {}, ["fields"] = {}}, ["y"] = 17, ["name"] = "building_blocks:hardwood", ["z"] = 5, ["param1"] = 15}, {["x"] = 6, ["meta"] = {["inventory"] = {}, ["fields"] = {}}, ["y"] = 17, ["name"] = "building_blocks:hardwood", ["z"] = 6, ["param1"] = 15}, {["x"] = 6, ["meta"] = {["inventory"] = {}, ["fields"] = {}}, ["y"] = 17, ["name"] = "building_blocks:hardwood", ["z"] = 7, ["param1"] = 15}, {["x"] = 6, ["meta"] = {["inventory"] = {}, ["fields"] = {}}, ["y"] = 17, ["name"] = "building_blocks:hardwood", ["z"] = 9, ["param1"] = 15}, {["x"] = 6, ["meta"] = {["inventory"] = {}, ["fields"] = {}}, ["y"] = 17, ["name"] = "building_blocks:hardwood", ["z"] = 10, ["param1"] = 15}, {["x"] = 6, ["meta"] = {["inventory"] = {}, ["fields"] = {}}, ["y"] = 17, ["name"] = "building_blocks:hardwood", ["z"] = 11, ["param1"] = 15}, {["x"] = 6, ["meta"] = {["inventory"] = {}, ["fields"] = {}}, ["y"] = 17, ["name"] = "building_blocks:hardwood", ["z"] = 12, ["param1"] = 15}, {["x"] = 6, ["meta"] = {["inventory"] = {}, ["fields"] = {}}, ["param2"] = 22, ["y"] = 17, ["name"] = "building_blocks:slope_hardwood_half_raised", ["z"] = 13, ["param1"] = 94}, {["x"] = 6, ["meta"] = {["inventory"] = {}, ["fields"] = {}}, ["y"] = 18, ["name"] = "ethereal:fence_redwood", ["z"] = 3, ["param1"] = 47}, {["x"] = 6, ["meta"] = {["inventory"] = {}, ["fields"] = {}}, ["param2"] = 4, ["y"] = 18, ["name"] = "ethereal:vine", ["z"] = 4, ["param1"] = 62}, {["x"] = 6, ["meta"] = {["inventory"] = {}, ["fields"] = {["palette_index"] = "0"}}, ["param2"] = 9, ["y"] = 18, ["name"] = "moreblocks:panel_wood_tile_full", ["z"] = 5, ["param1"] = 77}, {["x"] = 6, ["meta"] = {["inventory"] = {}, ["fields"] = {}}, ["param2"] = 7, ["y"] = 18, ["name"] = "moreblocks:slab_coal_glass_1", ["z"] = 6, ["param1"] = 92}, {["x"] = 6, ["meta"] = {["inventory"] = {}, ["fields"] = {}}, ["param2"] = 4, ["y"] = 18, ["name"] = "moreblocks:slab_wood_tile_full", ["z"] = 11, ["param1"] = 141}, {["x"] = 6, ["meta"] = {["inventory"] = {}, ["fields"] = {}}, ["y"] = 18, ["name"] = "ethereal:fence_redwood", ["z"] = 13, ["param1"] = 111}, {["x"] = 6, ["meta"] = {["inventory"] = {}, ["fields"] = {}}, ["param2"] = 4, ["y"] = 19, ["name"] = "ethereal:vine", ["z"] = 4, ["param1"] = 46}, {["x"] = 6, ["meta"] = {["inventory"] = {}, ["fields"] = {}}, ["param2"] = 9, ["y"] = 19, ["name"] = "moreblocks:slab_wood_tile_full", ["z"] = 5, ["param1"] = 61}, {["x"] = 6, ["meta"] = {["inventory"] = {}, ["fields"] = {}}, ["param2"] = 4, ["y"] = 19, ["name"] = "moreblocks:slab_coal_glass", ["z"] = 11, ["param1"] = 125}, {["x"] = 6, ["meta"] = {["inventory"] = {}, ["fields"] = {}}, ["param2"] = 4, ["y"] = 20, ["name"] = "ethereal:vine", ["z"] = 4, ["param1"] = 30}, {["x"] = 6, ["meta"] = {["inventory"] = {}, ["fields"] = {}}, ["param2"] = 9, ["y"] = 20, ["name"] = "moreblocks:slab_wood_tile_full", ["z"] = 5, ["param1"] = 45}, {["x"] = 6, ["meta"] = {["inventory"] = {}, ["fields"] = {}}, ["param2"] = 4, ["y"] = 20, ["name"] = "moreblocks:slab_coal_glass", ["z"] = 11, ["param1"] = 109}, {["x"] = 6, ["meta"] = {["inventory"] = {}, ["fields"] = {}}, ["y"] = 21, ["name"] = "moreblocks:slope_copperpatina_half", ["z"] = 4, ["param1"] = 14}, {["x"] = 6, ["meta"] = {["inventory"] = {}, ["fields"] = {}}, ["y"] = 21, ["name"] = "moreblocks:slope_copperpatina_half_raised", ["z"] = 5, ["param1"] = 30}, {["x"] = 6, ["meta"] = {["inventory"] = {}, ["fields"] = {}}, ["y"] = 21, ["name"] = "moreblocks:copperpatina", ["z"] = 6}, {["x"] = 6, ["meta"] = {["inventory"] = {}, ["fields"] = {}}, ["y"] = 21, ["name"] = "moreblocks:copperpatina", ["z"] = 7}, {["x"] = 6, ["meta"] = {["inventory"] = {}, ["fields"] = {}}, ["y"] = 21, ["name"] = "moreblocks:copperpatina", ["z"] = 10}, {["x"] = 6, ["meta"] = {["inventory"] = {}, ["fields"] = {}}, ["param2"] = 2, ["y"] = 21, ["name"] = "moreblocks:slope_copperpatina_half_raised", ["z"] = 11, ["param1"] = 94}, {["x"] = 6, ["meta"] = {["inventory"] = {}, ["fields"] = {}}, ["param2"] = 2, ["y"] = 21, ["name"] = "moreblocks:slope_copperpatina_half", ["z"] = 12, ["param1"] = 78}, {["x"] = 6, ["meta"] = {["inventory"] = {}, ["fields"] = {}}, ["y"] = 22, ["name"] = "moreblocks:slope_copperpatina", ["z"] = 6, ["param1"] = 14}, {["x"] = 6, ["meta"] = {["inventory"] = {}, ["fields"] = {}}, ["y"] = 22, ["name"] = "moreblocks:copperpatina", ["z"] = 7}, {["x"] = 6, ["meta"] = {["inventory"] = {}, ["fields"] = {}}, ["y"] = 22, ["name"] = "moreblocks:copperpatina", ["z"] = 8}, {["x"] = 6, ["meta"] = {["inventory"] = {}, ["fields"] = {}}, ["y"] = 22, ["name"] = "moreblocks:copperpatina", ["z"] = 9}, {["x"] = 6, ["meta"] = {["inventory"] = {}, ["fields"] = {}}, ["param2"] = 2, ["y"] = 22, ["name"] = "moreblocks:slope_copperpatina", ["z"] = 10, ["param1"] = 62}, {["x"] = 6, ["meta"] = {["inventory"] = {}, ["fields"] = {}}, ["param2"] = 1, ["y"] = 23, ["name"] = "moreblocks:slope_copperpatina_outer", ["z"] = 7, ["param1"] = 14}, {["x"] = 6, ["meta"] = {["inventory"] = {}, ["fields"] = {}}, ["param2"] = 19, ["y"] = 23, ["name"] = "moreblocks:slope_copperpatina_half_raised", ["z"] = 8, ["param1"] = 14}, {["x"] = 6, ["meta"] = {["inventory"] = {}, ["fields"] = {}}, ["param2"] = 2, ["y"] = 23, ["name"] = "moreblocks:slope_copperpatina_outer", ["z"] = 9, ["param1"] = 30}, {["x"] = 6, ["meta"] = {["inventory"] = {}, ["fields"] = {}}, ["param2"] = 19, ["y"] = 24, ["name"] = "moreblocks:slope_copperpatina_half", ["z"] = 8, ["param1"] = 14}, {["x"] = 7, ["meta"] = {["inventory"] = {}, ["fields"] = {}}, ["y"] = 0, ["name"] = "default:water_source", ["z"] = 0, ["param1"] = 14}, {["x"] = 7, ["meta"] = {["inventory"] = {}, ["fields"] = {}}, ["y"] = 0, ["name"] = "default:water_source", ["z"] = 1, ["param1"] = 14}, {["x"] = 7, ["meta"] = {["inventory"] = {}, ["fields"] = {}}, ["y"] = 0, ["name"] = "default:water_source", ["z"] = 2, ["param1"] = 14}, {["x"] = 7, ["meta"] = {["inventory"] = {}, ["fields"] = {}}, ["y"] = 0, ["name"] = "default:water_source", ["z"] = 3, ["param1"] = 13}, {["x"] = 7, ["meta"] = {["inventory"] = {}, ["fields"] = {}}, ["param2"] = 240, ["y"] = 0, ["name"] = "default:water_source", ["z"] = 4, ["param1"] = 12}, {["x"] = 7, ["meta"] = {["inventory"] = {}, ["fields"] = {}}, ["param2"] = 240, ["y"] = 0, ["name"] = "default:water_source", ["z"] = 5, ["param1"] = 11}, {["x"] = 7, ["meta"] = {["inventory"] = {}, ["fields"] = {}}, ["param2"] = 240, ["y"] = 0, ["name"] = "default:water_source", ["z"] = 6, ["param1"] = 10}, {["x"] = 7, ["meta"] = {["inventory"] = {}, ["fields"] = {}}, ["param2"] = 240, ["y"] = 0, ["name"] = "default:water_source", ["z"] = 7, ["param1"] = 9}, {["x"] = 7, ["meta"] = {["inventory"] = {}, ["fields"] = {}}, ["param2"] = 240, ["y"] = 0, ["name"] = "default:water_source", ["z"] = 8, ["param1"] = 8}, {["x"] = 7, ["meta"] = {["inventory"] = {}, ["fields"] = {}}, ["param2"] = 240, ["y"] = 0, ["name"] = "default:water_source", ["z"] = 9, ["param1"] = 9}, {["x"] = 7, ["meta"] = {["inventory"] = {}, ["fields"] = {}}, ["param2"] = 240, ["y"] = 0, ["name"] = "default:water_source", ["z"] = 10, ["param1"] = 10}, {["x"] = 7, ["meta"] = {["inventory"] = {}, ["fields"] = {}}, ["param2"] = 240, ["y"] = 0, ["name"] = "default:water_source", ["z"] = 11, ["param1"] = 11}, {["x"] = 7, ["meta"] = {["inventory"] = {}, ["fields"] = {}}, ["param2"] = 240, ["y"] = 0, ["name"] = "default:water_source", ["z"] = 12, ["param1"] = 12}, {["x"] = 7, ["meta"] = {["inventory"] = {}, ["fields"] = {}}, ["y"] = 0, ["name"] = "default:water_source", ["z"] = 13, ["param1"] = 13}, {["x"] = 7, ["meta"] = {["inventory"] = {}, ["fields"] = {}}, ["y"] = 0, ["name"] = "default:water_source", ["z"] = 14, ["param1"] = 14}, {["x"] = 7, ["meta"] = {["inventory"] = {}, ["fields"] = {}}, ["y"] = 0, ["name"] = "default:water_source", ["z"] = 15, ["param1"] = 14}, {["x"] = 7, ["meta"] = {["inventory"] = {}, ["fields"] = {}}, ["y"] = 0, ["name"] = "default:water_source", ["z"] = 16, ["param1"] = 14}, {["x"] = 7, ["meta"] = {["inventory"] = {}, ["fields"] = {}}, ["param2"] = 21, ["y"] = 1, ["name"] = "moreblocks:slab_wood_tile_full", ["z"] = 5, ["param1"] = 12}, {["x"] = 7, ["meta"] = {["inventory"] = {}, ["fields"] = {}}, ["param2"] = 21, ["y"] = 1, ["name"] = "moreblocks:slab_wood_tile_full", ["z"] = 6, ["param1"] = 11}, {["x"] = 7, ["meta"] = {["inventory"] = {}, ["fields"] = {}}, ["param2"] = 21, ["y"] = 1, ["name"] = "moreblocks:slab_wood_tile_full", ["z"] = 7, ["param1"] = 10}, {["x"] = 7, ["meta"] = {["inventory"] = {}, ["fields"] = {}}, ["param2"] = 21, ["y"] = 1, ["name"] = "moreblocks:slab_wood_tile_full", ["z"] = 8, ["param1"] = 9}, {["x"] = 7, ["meta"] = {["inventory"] = {}, ["fields"] = {}}, ["param2"] = 21, ["y"] = 1, ["name"] = "moreblocks:slab_wood_tile_full", ["z"] = 9, ["param1"] = 10}, {["x"] = 7, ["meta"] = {["inventory"] = {}, ["fields"] = {}}, ["param2"] = 21, ["y"] = 1, ["name"] = "moreblocks:slab_wood_tile_full", ["z"] = 10, ["param1"] = 11}, {["x"] = 7, ["meta"] = {["inventory"] = {}, ["fields"] = {}}, ["param2"] = 21, ["y"] = 1, ["name"] = "moreblocks:slab_wood_tile_full", ["z"] = 11, ["param1"] = 12}, {["x"] = 7, ["meta"] = {["inventory"] = {}, ["fields"] = {}}, ["param2"] = 21, ["y"] = 7, ["name"] = "moreblocks:slab_wood_tile_full", ["z"] = 6, ["param1"] = 11}, {["x"] = 7, ["meta"] = {["inventory"] = {}, ["fields"] = {}}, ["param2"] = 21, ["y"] = 7, ["name"] = "moreblocks:slab_wood_tile_full", ["z"] = 7, ["param1"] = 10}, {["x"] = 7, ["meta"] = {["inventory"] = {}, ["fields"] = {}}, ["param2"] = 21, ["y"] = 7, ["name"] = "moreblocks:slab_wood_tile_full", ["z"] = 8, ["param1"] = 9}, {["x"] = 7, ["meta"] = {["inventory"] = {}, ["fields"] = {}}, ["param2"] = 21, ["y"] = 7, ["name"] = "moreblocks:slab_wood_tile_full", ["z"] = 9, ["param1"] = 10}, {["x"] = 7, ["meta"] = {["inventory"] = {}, ["fields"] = {}}, ["param2"] = 21, ["y"] = 7, ["name"] = "moreblocks:slab_wood_tile_full", ["z"] = 10, ["param1"] = 11}, {["x"] = 7, ["meta"] = {["inventory"] = {}, ["fields"] = {}}, ["param2"] = 21, ["y"] = 11, ["name"] = "moreblocks:slab_wood_tile_full", ["z"] = 6, ["param1"] = 11}, {["x"] = 7, ["meta"] = {["inventory"] = {}, ["fields"] = {}}, ["param2"] = 21, ["y"] = 11, ["name"] = "moreblocks:slab_wood_tile_full", ["z"] = 7, ["param1"] = 10}, {["x"] = 7, ["meta"] = {["inventory"] = {}, ["fields"] = {}}, ["param2"] = 21, ["y"] = 11, ["name"] = "moreblocks:slab_wood_tile_full", ["z"] = 8, ["param1"] = 9}, {["x"] = 7, ["meta"] = {["inventory"] = {}, ["fields"] = {}}, ["param2"] = 21, ["y"] = 11, ["name"] = "moreblocks:slab_wood_tile_full", ["z"] = 9, ["param1"] = 10}, {["x"] = 7, ["meta"] = {["inventory"] = {}, ["fields"] = {}}, ["param2"] = 21, ["y"] = 11, ["name"] = "moreblocks:slab_wood_tile_full", ["z"] = 10, ["param1"] = 11}, {["x"] = 7, ["meta"] = {["inventory"] = {}, ["fields"] = {}}, ["param2"] = 8, ["y"] = 16, ["name"] = "building_blocks:slope_hardwood_half_raised", ["z"] = 4, ["param1"] = 13}, {["x"] = 7, ["meta"] = {["inventory"] = {}, ["fields"] = {}}, ["param2"] = 6, ["y"] = 16, ["name"] = "building_blocks:slope_hardwood_half_raised", ["z"] = 12, ["param1"] = 45}, {["x"] = 7, ["meta"] = {["inventory"] = {}, ["fields"] = {}}, ["param2"] = 20, ["y"] = 17, ["name"] = "building_blocks:slope_hardwood_half_raised", ["z"] = 3, ["param1"] = 14}, {["x"] = 7, ["meta"] = {["inventory"] = {}, ["fields"] = {}}, ["y"] = 17, ["name"] = "building_blocks:hardwood", ["z"] = 4, ["param1"] = 14}, {["x"] = 7, ["meta"] = {["inventory"] = {}, ["fields"] = {}}, ["y"] = 17, ["name"] = "building_blocks:hardwood", ["z"] = 5, ["param1"] = 15}, {["x"] = 7, ["meta"] = {["inventory"] = {}, ["fields"] = {}}, ["y"] = 17, ["name"] = "building_blocks:hardwood", ["z"] = 6, ["param1"] = 15}, {["x"] = 7, ["meta"] = {["inventory"] = {}, ["fields"] = {}}, ["y"] = 17, ["name"] = "building_blocks:hardwood", ["z"] = 7, ["param1"] = 15}, {["x"] = 7, ["meta"] = {["inventory"] = {}, ["fields"] = {}}, ["y"] = 17, ["name"] = "building_blocks:hardwood", ["z"] = 8, ["param1"] = 15}, {["x"] = 7, ["meta"] = {["inventory"] = {}, ["fields"] = {}}, ["y"] = 17, ["name"] = "building_blocks:hardwood", ["z"] = 9, ["param1"] = 15}, {["x"] = 7, ["meta"] = {["inventory"] = {}, ["fields"] = {}}, ["y"] = 17, ["name"] = "building_blocks:hardwood", ["z"] = 10, ["param1"] = 15}, {["x"] = 7, ["meta"] = {["inventory"] = {}, ["fields"] = {}}, ["y"] = 17, ["name"] = "building_blocks:hardwood", ["z"] = 11, ["param1"] = 15}, {["x"] = 7, ["meta"] = {["inventory"] = {}, ["fields"] = {}}, ["y"] = 17, ["name"] = "building_blocks:hardwood", ["z"] = 12, ["param1"] = 15}, {["x"] = 7, ["meta"] = {["inventory"] = {}, ["fields"] = {}}, ["param2"] = 22, ["y"] = 17, ["name"] = "building_blocks:slope_hardwood_half_raised", ["z"] = 13, ["param1"] = 78}, {["x"] = 7, ["meta"] = {["inventory"] = {}, ["fields"] = {}}, ["y"] = 18, ["name"] = "ethereal:fence_redwood", ["z"] = 3, ["param1"] = 31}, {["x"] = 7, ["meta"] = {["inventory"] = {}, ["fields"] = {}}, ["param2"] = 9, ["y"] = 18, ["name"] = "moreblocks:slab_wood_tile_full", ["z"] = 5, ["param1"] = 61}, {["x"] = 7, ["meta"] = {["inventory"] = {}, ["fields"] = {}}, ["param2"] = 4, ["y"] = 18, ["name"] = "moreblocks:slab_wood_tile_full", ["z"] = 11, ["param1"] = 125}, {["x"] = 7, ["meta"] = {["inventory"] = {}, ["fields"] = {}}, ["y"] = 18, ["name"] = "ethereal:fence_redwood", ["z"] = 13, ["param1"] = 95}, {["x"] = 7, ["meta"] = {["inventory"] = {}, ["fields"] = {}}, ["param2"] = 9, ["y"] = 19, ["name"] = "moreblocks:panel_wood_tile_full", ["z"] = 5, ["param1"] = 45}, {["x"] = 7, ["meta"] = {["inventory"] = {}, ["fields"] = {}}, ["param2"] = 7, ["y"] = 19, ["name"] = "moreblocks:slab_coal_glass_1", ["z"] = 6, ["param1"] = 60}, {["x"] = 7, ["meta"] = {["inventory"] = {}, ["fields"] = {}}, ["param2"] = 4, ["y"] = 19, ["name"] = "moreblocks:slab_wood_tile_full", ["z"] = 11, ["param1"] = 109}, {["x"] = 7, ["meta"] = {["inventory"] = {}, ["fields"] = {}}, ["param2"] = 4, ["y"] = 20, ["name"] = "ethereal:vine", ["z"] = 4, ["param1"] = 14}, {["x"] = 7, ["meta"] = {["inventory"] = {}, ["fields"] = {}}, ["param2"] = 9, ["y"] = 20, ["name"] = "moreblocks:slab_wood_tile_full", ["z"] = 5, ["param1"] = 29}, {["x"] = 7, ["meta"] = {["inventory"] = {}, ["fields"] = {}}, ["param2"] = 4, ["y"] = 20, ["name"] = "moreblocks:slab_wood_tile_full", ["z"] = 11, ["param1"] = 93}, {["x"] = 7, ["meta"] = {["inventory"] = {}, ["fields"] = {}}, ["y"] = 21, ["name"] = "moreblocks:slope_copperpatina_half", ["z"] = 4, ["param1"] = 14}, {["x"] = 7, ["meta"] = {["inventory"] = {}, ["fields"] = {}}, ["y"] = 21, ["name"] = "moreblocks:slope_copperpatina_half_raised", ["z"] = 5, ["param1"] = 14}, {["x"] = 7, ["meta"] = {["inventory"] = {}, ["fields"] = {}}, ["y"] = 21, ["name"] = "moreblocks:copperpatina", ["z"] = 6}, {["x"] = 7, ["meta"] = {["inventory"] = {}, ["fields"] = {}}, ["y"] = 21, ["name"] = "moreblocks:copperpatina", ["z"] = 10}, {["x"] = 7, ["meta"] = {["inventory"] = {}, ["fields"] = {}}, ["param2"] = 2, ["y"] = 21, ["name"] = "moreblocks:slope_copperpatina_half_raised", ["z"] = 11, ["param1"] = 78}, {["x"] = 7, ["meta"] = {["inventory"] = {}, ["fields"] = {}}, ["param2"] = 2, ["y"] = 21, ["name"] = "moreblocks:slope_copperpatina_half", ["z"] = 12, ["param1"] = 62}, {["x"] = 7, ["meta"] = {["inventory"] = {}, ["fields"] = {}}, ["y"] = 22, ["name"] = "moreblocks:slope_copperpatina", ["z"] = 6, ["param1"] = 14}, {["x"] = 7, ["meta"] = {["inventory"] = {}, ["fields"] = {}}, ["y"] = 22, ["name"] = "moreblocks:copperpatina", ["z"] = 7}, {["x"] = 7, ["meta"] = {["inventory"] = {}, ["fields"] = {}}, ["y"] = 22, ["name"] = "moreblocks:copperpatina", ["z"] = 8}, {["x"] = 7, ["meta"] = {["inventory"] = {}, ["fields"] = {}}, ["y"] = 22, ["name"] = "moreblocks:copperpatina", ["z"] = 9}, {["x"] = 7, ["meta"] = {["inventory"] = {}, ["fields"] = {}}, ["param2"] = 2, ["y"] = 22, ["name"] = "moreblocks:slope_copperpatina", ["z"] = 10, ["param1"] = 46}, {["x"] = 7, ["meta"] = {["inventory"] = {}, ["fields"] = {}}, ["param2"] = 10, ["y"] = 23, ["name"] = "moreblocks:slope_copperpatina_half_raised", ["z"] = 7, ["param1"] = 14}, {["x"] = 7, ["meta"] = {["inventory"] = {}, ["fields"] = {}}, ["param2"] = 4, ["y"] = 23, ["name"] = "moreblocks:slope_copperpatina_half_raised", ["z"] = 9, ["param1"] = 14}, {["x"] = 7, ["meta"] = {["inventory"] = {}, ["fields"] = {}}, ["param2"] = 10, ["y"] = 24, ["name"] = "moreblocks:slope_copperpatina_half", ["z"] = 7, ["param1"] = 14}, {["x"] = 7, ["meta"] = {["inventory"] = {}, ["fields"] = {}}, ["param2"] = 4, ["y"] = 24, ["name"] = "moreblocks:slope_copperpatina_half", ["z"] = 9, ["param1"] = 14}, {["x"] = 8, ["meta"] = {["inventory"] = {}, ["fields"] = {}}, ["y"] = 0, ["name"] = "default:water_source", ["z"] = 0, ["param1"] = 14}, {["x"] = 8, ["meta"] = {["inventory"] = {}, ["fields"] = {}}, ["y"] = 0, ["name"] = "default:water_source", ["z"] = 1, ["param1"] = 14}, {["x"] = 8, ["meta"] = {["inventory"] = {}, ["fields"] = {}}, ["y"] = 0, ["name"] = "default:water_source", ["z"] = 2, ["param1"] = 14}, {["x"] = 8, ["meta"] = {["inventory"] = {}, ["fields"] = {}}, ["y"] = 0, ["name"] = "default:water_source", ["z"] = 3, ["param1"] = 13}, {["x"] = 8, ["meta"] = {["inventory"] = {}, ["fields"] = {}}, ["y"] = 0, ["name"] = "default:water_source", ["z"] = 4, ["param1"] = 12}, {["x"] = 8, ["meta"] = {["inventory"] = {}, ["fields"] = {}}, ["y"] = 0, ["name"] = "default:water_source", ["z"] = 5, ["param1"] = 11}, {["x"] = 8, ["meta"] = {["inventory"] = {}, ["fields"] = {}}, ["y"] = 0, ["name"] = "default:water_source", ["z"] = 6, ["param1"] = 10}, {["x"] = 8, ["meta"] = {["inventory"] = {}, ["fields"] = {}}, ["y"] = 0, ["name"] = "default:water_source", ["z"] = 7, ["param1"] = 9}, {["x"] = 8, ["meta"] = {["inventory"] = {}, ["fields"] = {}}, ["y"] = 0, ["name"] = "default:water_source", ["z"] = 8, ["param1"] = 8}, {["x"] = 8, ["meta"] = {["inventory"] = {}, ["fields"] = {}}, ["y"] = 0, ["name"] = "default:water_source", ["z"] = 9, ["param1"] = 9}, {["x"] = 8, ["meta"] = {["inventory"] = {}, ["fields"] = {}}, ["y"] = 0, ["name"] = "default:water_source", ["z"] = 10, ["param1"] = 10}, {["x"] = 8, ["meta"] = {["inventory"] = {}, ["fields"] = {}}, ["y"] = 0, ["name"] = "default:water_source", ["z"] = 11, ["param1"] = 11}, {["x"] = 8, ["meta"] = {["inventory"] = {}, ["fields"] = {}}, ["y"] = 0, ["name"] = "default:water_source", ["z"] = 12, ["param1"] = 12}, {["x"] = 8, ["meta"] = {["inventory"] = {}, ["fields"] = {}}, ["y"] = 0, ["name"] = "default:water_source", ["z"] = 13, ["param1"] = 13}, {["x"] = 8, ["meta"] = {["inventory"] = {}, ["fields"] = {}}, ["y"] = 0, ["name"] = "default:water_source", ["z"] = 14, ["param1"] = 14}, {["x"] = 8, ["meta"] = {["inventory"] = {}, ["fields"] = {}}, ["y"] = 0, ["name"] = "default:water_source", ["z"] = 15, ["param1"] = 14}, {["x"] = 8, ["meta"] = {["inventory"] = {}, ["fields"] = {}}, ["y"] = 0, ["name"] = "default:water_source", ["z"] = 16, ["param1"] = 14}, {["x"] = 8, ["meta"] = {["inventory"] = {}, ["fields"] = {}}, ["param2"] = 21, ["y"] = 1, ["name"] = "moreblocks:slab_wood_tile_full", ["z"] = 5, ["param1"] = 12}, {["x"] = 8, ["meta"] = {["inventory"] = {}, ["fields"] = {}}, ["param2"] = 21, ["y"] = 1, ["name"] = "moreblocks:slab_wood_tile_full", ["z"] = 6, ["param1"] = 11}, {["x"] = 8, ["meta"] = {["inventory"] = {}, ["fields"] = {}}, ["param2"] = 21, ["y"] = 1, ["name"] = "moreblocks:slab_wood_tile_full", ["z"] = 7, ["param1"] = 10}, {["x"] = 8, ["meta"] = {["inventory"] = {}, ["fields"] = {}}, ["param2"] = 21, ["y"] = 1, ["name"] = "moreblocks:slab_wood_tile_full", ["z"] = 8, ["param1"] = 9}, {["x"] = 8, ["meta"] = {["inventory"] = {}, ["fields"] = {}}, ["param2"] = 21, ["y"] = 1, ["name"] = "moreblocks:slab_wood_tile_full", ["z"] = 9, ["param1"] = 10}, {["x"] = 8, ["meta"] = {["inventory"] = {}, ["fields"] = {}}, ["param2"] = 21, ["y"] = 1, ["name"] = "moreblocks:slab_wood_tile_full", ["z"] = 10, ["param1"] = 11}, {["x"] = 8, ["meta"] = {["inventory"] = {}, ["fields"] = {}}, ["param2"] = 21, ["y"] = 1, ["name"] = "moreblocks:slab_wood_tile_full", ["z"] = 11, ["param1"] = 12}, {["x"] = 8, ["meta"] = {["inventory"] = {}, ["fields"] = {}}, ["param2"] = 21, ["y"] = 7, ["name"] = "moreblocks:slab_wood_tile_full", ["z"] = 6, ["param1"] = 11}, {["x"] = 8, ["meta"] = {["inventory"] = {}, ["fields"] = {}}, ["param2"] = 21, ["y"] = 7, ["name"] = "moreblocks:slab_wood_tile_full", ["z"] = 7, ["param1"] = 10}, {["x"] = 8, ["meta"] = {["inventory"] = {}, ["fields"] = {}}, ["param2"] = 21, ["y"] = 7, ["name"] = "moreblocks:slab_wood_tile_full", ["z"] = 8, ["param1"] = 9}, {["x"] = 8, ["meta"] = {["inventory"] = {}, ["fields"] = {}}, ["param2"] = 21, ["y"] = 7, ["name"] = "moreblocks:slab_wood_tile_full", ["z"] = 9, ["param1"] = 10}, {["x"] = 8, ["meta"] = {["inventory"] = {}, ["fields"] = {}}, ["param2"] = 21, ["y"] = 7, ["name"] = "moreblocks:slab_wood_tile_full", ["z"] = 10, ["param1"] = 11}, {["x"] = 8, ["meta"] = {["inventory"] = {}, ["fields"] = {}}, ["param2"] = 21, ["y"] = 11, ["name"] = "moreblocks:slab_wood_tile_full", ["z"] = 6, ["param1"] = 11}, {["x"] = 8, ["meta"] = {["inventory"] = {}, ["fields"] = {}}, ["param2"] = 21, ["y"] = 11, ["name"] = "moreblocks:slab_wood_tile_full", ["z"] = 7, ["param1"] = 10}, {["x"] = 8, ["meta"] = {["inventory"] = {}, ["fields"] = {}}, ["param2"] = 21, ["y"] = 11, ["name"] = "moreblocks:slab_wood_tile_full", ["z"] = 8, ["param1"] = 9}, {["x"] = 8, ["meta"] = {["inventory"] = {}, ["fields"] = {}}, ["param2"] = 21, ["y"] = 11, ["name"] = "moreblocks:slab_wood_tile_full", ["z"] = 9, ["param1"] = 10}, {["x"] = 8, ["meta"] = {["inventory"] = {}, ["fields"] = {}}, ["param2"] = 21, ["y"] = 11, ["name"] = "moreblocks:slab_wood_tile_full", ["z"] = 10, ["param1"] = 11}, {["x"] = 8, ["meta"] = {["inventory"] = {}, ["fields"] = {}}, ["param2"] = 8, ["y"] = 16, ["name"] = "building_blocks:slope_hardwood_half_raised", ["z"] = 4, ["param1"] = 13}, {["x"] = 8, ["meta"] = {["inventory"] = {}, ["fields"] = {}}, ["param2"] = 6, ["y"] = 16, ["name"] = "building_blocks:slope_hardwood_half_raised", ["z"] = 12, ["param1"] = 29}, {["x"] = 8, ["meta"] = {["inventory"] = {}, ["fields"] = {}}, ["param2"] = 20, ["y"] = 17, ["name"] = "building_blocks:slope_hardwood_half_raised", ["z"] = 3, ["param1"] = 14}, {["x"] = 8, ["meta"] = {["inventory"] = {}, ["fields"] = {}}, ["y"] = 17, ["name"] = "building_blocks:hardwood", ["z"] = 4, ["param1"] = 15}, {["x"] = 8, ["meta"] = {["inventory"] = {}, ["fields"] = {}}, ["y"] = 17, ["name"] = "building_blocks:hardwood", ["z"] = 5, ["param1"] = 15}, {["x"] = 8, ["meta"] = {["inventory"] = {}, ["fields"] = {}}, ["y"] = 17, ["name"] = "building_blocks:hardwood", ["z"] = 6, ["param1"] = 15}, {["x"] = 8, ["meta"] = {["inventory"] = {}, ["fields"] = {}}, ["y"] = 17, ["name"] = "building_blocks:hardwood", ["z"] = 7, ["param1"] = 15}, {["x"] = 8, ["meta"] = {["inventory"] = {}, ["fields"] = {}}, ["y"] = 17, ["name"] = "building_blocks:hardwood", ["z"] = 8, ["param1"] = 15}, {["x"] = 8, ["meta"] = {["inventory"] = {}, ["fields"] = {}}, ["y"] = 17, ["name"] = "building_blocks:hardwood", ["z"] = 9, ["param1"] = 15}, {["x"] = 8, ["meta"] = {["inventory"] = {}, ["fields"] = {}}, ["y"] = 17, ["name"] = "building_blocks:hardwood", ["z"] = 10, ["param1"] = 15}, {["x"] = 8, ["meta"] = {["inventory"] = {}, ["fields"] = {}}, ["y"] = 17, ["name"] = "building_blocks:hardwood", ["z"] = 11, ["param1"] = 15}, {["x"] = 8, ["meta"] = {["inventory"] = {}, ["fields"] = {}}, ["y"] = 17, ["name"] = "building_blocks:hardwood", ["z"] = 12, ["param1"] = 15}, {["x"] = 8, ["meta"] = {["inventory"] = {}, ["fields"] = {}}, ["param2"] = 22, ["y"] = 17, ["name"] = "building_blocks:slope_hardwood_half_raised", ["z"] = 13, ["param1"] = 62}, {["x"] = 8, ["meta"] = {["inventory"] = {}, ["fields"] = {}}, ["y"] = 18, ["name"] = "ethereal:fence_redwood", ["z"] = 3, ["param1"] = 15}, {["x"] = 8, ["meta"] = {["inventory"] = {}, ["fields"] = {}}, ["param2"] = 9, ["y"] = 18, ["name"] = "moreblocks:slab_wood_tile_full", ["z"] = 5, ["param1"] = 45}, {["x"] = 8, ["meta"] = {["inventory"] = {}, ["fields"] = {}}, ["y"] = 18, ["name"] = "ethereal:fence_redwood", ["z"] = 13, ["param1"] = 79}, {["x"] = 8, ["meta"] = {["inventory"] = {}, ["fields"] = {}}, ["param2"] = 9, ["y"] = 19, ["name"] = "moreblocks:slab_wood_tile_full", ["z"] = 5, ["param1"] = 29}, {["x"] = 8, ["meta"] = {["inventory"] = {}, ["fields"] = {}}, ["param2"] = 9, ["y"] = 20, ["name"] = "moreblocks:panel_wood_tile_full", ["z"] = 5, ["param1"] = 13}, {["x"] = 8, ["meta"] = {["inventory"] = {}, ["fields"] = {}}, ["param2"] = 7, ["y"] = 20, ["name"] = "moreblocks:slab_coal_glass_1", ["z"] = 6, ["param1"] = 28}, {["x"] = 8, ["meta"] = {["inventory"] = {}, ["fields"] = {}}, ["y"] = 21, ["name"] = "moreblocks:slope_copperpatina_half", ["z"] = 4, ["param1"] = 14}, {["x"] = 8, ["meta"] = {["inventory"] = {}, ["fields"] = {}}, ["y"] = 21, ["name"] = "moreblocks:slope_copperpatina_half_raised", ["z"] = 5, ["param1"] = 14}, {["x"] = 8, ["meta"] = {["inventory"] = {}, ["fields"] = {}}, ["y"] = 21, ["name"] = "moreblocks:copperpatina", ["z"] = 6}, {["x"] = 8, ["meta"] = {["inventory"] = {}, ["fields"] = {}}, ["y"] = 21, ["name"] = "moreblocks:copperpatina", ["z"] = 10}, {["x"] = 8, ["meta"] = {["inventory"] = {}, ["fields"] = {}}, ["param2"] = 2, ["y"] = 21, ["name"] = "moreblocks:slope_copperpatina_half_raised", ["z"] = 11, ["param1"] = 62}, {["x"] = 8, ["meta"] = {["inventory"] = {}, ["fields"] = {}}, ["param2"] = 2, ["y"] = 21, ["name"] = "moreblocks:slope_copperpatina_half", ["z"] = 12, ["param1"] = 46}, {["x"] = 8, ["meta"] = {["inventory"] = {}, ["fields"] = {}}, ["y"] = 22, ["name"] = "moreblocks:slope_copperpatina", ["z"] = 6, ["param1"] = 14}, {["x"] = 8, ["meta"] = {["inventory"] = {}, ["fields"] = {}}, ["y"] = 22, ["name"] = "moreblocks:copperpatina", ["z"] = 7}, {["x"] = 8, ["meta"] = {["inventory"] = {}, ["fields"] = {}}, ["y"] = 22, ["name"] = "moreblocks:copperpatina", ["z"] = 8}, {["x"] = 8, ["meta"] = {["inventory"] = {}, ["fields"] = {}}, ["y"] = 22, ["name"] = "moreblocks:copperpatina", ["z"] = 9}, {["x"] = 8, ["meta"] = {["inventory"] = {}, ["fields"] = {}}, ["param2"] = 2, ["y"] = 22, ["name"] = "moreblocks:slope_copperpatina", ["z"] = 10, ["param1"] = 30}, {["x"] = 8, ["meta"] = {["inventory"] = {}, ["fields"] = {}}, ["param2"] = 10, ["y"] = 23, ["name"] = "moreblocks:slope_copperpatina_half_raised", ["z"] = 7, ["param1"] = 14}, {["x"] = 8, ["meta"] = {["inventory"] = {}, ["fields"] = {}}, ["param2"] = 4, ["y"] = 23, ["name"] = "moreblocks:slope_copperpatina_half_raised", ["z"] = 9, ["param1"] = 14}, {["x"] = 8, ["meta"] = {["inventory"] = {}, ["fields"] = {}}, ["param2"] = 10, ["y"] = 24, ["name"] = "moreblocks:slope_copperpatina_half", ["z"] = 7, ["param1"] = 14}, {["x"] = 8, ["meta"] = {["inventory"] = {}, ["fields"] = {}}, ["param2"] = 4, ["y"] = 24, ["name"] = "moreblocks:slope_copperpatina_half", ["z"] = 9, ["param1"] = 14}, {["x"] = 8, ["meta"] = {["inventory"] = {}, ["fields"] = {}}, ["param2"] = 16, ["y"] = 26, ["name"] = "moreblocks:slab_copperpatina_quarter", ["z"] = 8, ["param1"] = 14}, {["x"] = 9, ["meta"] = {["inventory"] = {}, ["fields"] = {}}, ["y"] = 0, ["name"] = "default:water_source", ["z"] = 0, ["param1"] = 14}, {["x"] = 9, ["meta"] = {["inventory"] = {}, ["fields"] = {}}, ["y"] = 0, ["name"] = "default:water_source", ["z"] = 1, ["param1"] = 14}, {["x"] = 9, ["meta"] = {["inventory"] = {}, ["fields"] = {}}, ["y"] = 0, ["name"] = "default:water_source", ["z"] = 2, ["param1"] = 14}, {["x"] = 9, ["meta"] = {["inventory"] = {}, ["fields"] = {}}, ["y"] = 0, ["name"] = "default:water_source", ["z"] = 3, ["param1"] = 13}, {["x"] = 9, ["meta"] = {["inventory"] = {}, ["fields"] = {}}, ["y"] = 0, ["name"] = "default:water_source", ["z"] = 4, ["param1"] = 12}, {["x"] = 9, ["meta"] = {["inventory"] = {}, ["fields"] = {}}, ["y"] = 0, ["name"] = "default:water_source", ["z"] = 5, ["param1"] = 11}, {["x"] = 9, ["meta"] = {["inventory"] = {}, ["fields"] = {}}, ["y"] = 0, ["name"] = "default:water_source", ["z"] = 6, ["param1"] = 10}, {["x"] = 9, ["meta"] = {["inventory"] = {}, ["fields"] = {}}, ["y"] = 0, ["name"] = "default:water_source", ["z"] = 7, ["param1"] = 9}, {["x"] = 9, ["meta"] = {["inventory"] = {}, ["fields"] = {}}, ["y"] = 0, ["name"] = "default:water_source", ["z"] = 8, ["param1"] = 8}, {["x"] = 9, ["meta"] = {["inventory"] = {}, ["fields"] = {}}, ["y"] = 0, ["name"] = "default:water_source", ["z"] = 9, ["param1"] = 9}, {["x"] = 9, ["meta"] = {["inventory"] = {}, ["fields"] = {}}, ["y"] = 0, ["name"] = "default:water_source", ["z"] = 10, ["param1"] = 10}, {["x"] = 9, ["meta"] = {["inventory"] = {}, ["fields"] = {}}, ["y"] = 0, ["name"] = "default:water_source", ["z"] = 11, ["param1"] = 11}, {["x"] = 9, ["meta"] = {["inventory"] = {}, ["fields"] = {}}, ["y"] = 0, ["name"] = "default:water_source", ["z"] = 12, ["param1"] = 12}, {["x"] = 9, ["meta"] = {["inventory"] = {}, ["fields"] = {}}, ["y"] = 0, ["name"] = "default:water_source", ["z"] = 13, ["param1"] = 13}, {["x"] = 9, ["meta"] = {["inventory"] = {}, ["fields"] = {}}, ["y"] = 0, ["name"] = "default:water_source", ["z"] = 14, ["param1"] = 14}, {["x"] = 9, ["meta"] = {["inventory"] = {}, ["fields"] = {}}, ["y"] = 0, ["name"] = "default:water_source", ["z"] = 15, ["param1"] = 14}, {["x"] = 9, ["meta"] = {["inventory"] = {}, ["fields"] = {}}, ["y"] = 0, ["name"] = "default:water_source", ["z"] = 16, ["param1"] = 14}, {["x"] = 9, ["meta"] = {["inventory"] = {}, ["fields"] = {}}, ["param2"] = 21, ["y"] = 1, ["name"] = "moreblocks:slab_wood_tile_full", ["z"] = 5, ["param1"] = 12}, {["x"] = 9, ["meta"] = {["inventory"] = {}, ["fields"] = {}}, ["param2"] = 21, ["y"] = 1, ["name"] = "moreblocks:slab_wood_tile_full", ["z"] = 6, ["param1"] = 11}, {["x"] = 9, ["meta"] = {["inventory"] = {}, ["fields"] = {}}, ["param2"] = 21, ["y"] = 1, ["name"] = "moreblocks:slab_wood_tile_full", ["z"] = 7, ["param1"] = 10}, {["x"] = 9, ["meta"] = {["inventory"] = {}, ["fields"] = {}}, ["param2"] = 21, ["y"] = 1, ["name"] = "moreblocks:slab_wood_tile_full", ["z"] = 8, ["param1"] = 9}, {["x"] = 9, ["meta"] = {["inventory"] = {}, ["fields"] = {}}, ["param2"] = 21, ["y"] = 1, ["name"] = "moreblocks:slab_wood_tile_full", ["z"] = 9, ["param1"] = 10}, {["x"] = 9, ["meta"] = {["inventory"] = {}, ["fields"] = {}}, ["param2"] = 21, ["y"] = 1, ["name"] = "moreblocks:slab_wood_tile_full", ["z"] = 10, ["param1"] = 11}, {["x"] = 9, ["meta"] = {["inventory"] = {}, ["fields"] = {}}, ["param2"] = 21, ["y"] = 1, ["name"] = "moreblocks:slab_wood_tile_full", ["z"] = 11, ["param1"] = 12}, {["x"] = 9, ["meta"] = {["inventory"] = {}, ["fields"] = {}}, ["param2"] = 21, ["y"] = 7, ["name"] = "moreblocks:slab_wood_tile_full", ["z"] = 6, ["param1"] = 11}, {["x"] = 9, ["meta"] = {["inventory"] = {}, ["fields"] = {}}, ["param2"] = 21, ["y"] = 7, ["name"] = "moreblocks:slab_wood_tile_full", ["z"] = 7, ["param1"] = 10}, {["x"] = 9, ["meta"] = {["inventory"] = {}, ["fields"] = {}}, ["param2"] = 21, ["y"] = 7, ["name"] = "moreblocks:slab_wood_tile_full", ["z"] = 8, ["param1"] = 9}, {["x"] = 9, ["meta"] = {["inventory"] = {}, ["fields"] = {}}, ["param2"] = 21, ["y"] = 7, ["name"] = "moreblocks:slab_wood_tile_full", ["z"] = 9, ["param1"] = 10}, {["x"] = 9, ["meta"] = {["inventory"] = {}, ["fields"] = {}}, ["param2"] = 21, ["y"] = 7, ["name"] = "moreblocks:slab_wood_tile_full", ["z"] = 10, ["param1"] = 11}, {["x"] = 9, ["meta"] = {["inventory"] = {}, ["fields"] = {}}, ["param2"] = 21, ["y"] = 11, ["name"] = "moreblocks:slab_wood_tile_full", ["z"] = 6, ["param1"] = 11}, {["x"] = 9, ["meta"] = {["inventory"] = {}, ["fields"] = {}}, ["param2"] = 21, ["y"] = 11, ["name"] = "moreblocks:slab_wood_tile_full", ["z"] = 7, ["param1"] = 10}, {["x"] = 9, ["meta"] = {["inventory"] = {}, ["fields"] = {}}, ["param2"] = 21, ["y"] = 11, ["name"] = "moreblocks:slab_wood_tile_full", ["z"] = 8, ["param1"] = 9}, {["x"] = 9, ["meta"] = {["inventory"] = {}, ["fields"] = {}}, ["param2"] = 21, ["y"] = 11, ["name"] = "moreblocks:slab_wood_tile_full", ["z"] = 9, ["param1"] = 10}, {["x"] = 9, ["meta"] = {["inventory"] = {}, ["fields"] = {}}, ["param2"] = 21, ["y"] = 11, ["name"] = "moreblocks:slab_wood_tile_full", ["z"] = 10, ["param1"] = 11}, {["x"] = 9, ["meta"] = {["inventory"] = {}, ["fields"] = {}}, ["param2"] = 8, ["y"] = 16, ["name"] = "building_blocks:slope_hardwood_half_raised", ["z"] = 4, ["param1"] = 13}, {["x"] = 9, ["meta"] = {["inventory"] = {}, ["fields"] = {}}, ["param2"] = 6, ["y"] = 16, ["name"] = "building_blocks:slope_hardwood_half_raised", ["z"] = 12, ["param1"] = 13}, {["x"] = 9, ["meta"] = {["inventory"] = {}, ["fields"] = {}}, ["param2"] = 20, ["y"] = 17, ["name"] = "building_blocks:slope_hardwood_half_raised", ["z"] = 3, ["param1"] = 14}, {["x"] = 9, ["meta"] = {["inventory"] = {}, ["fields"] = {}}, ["y"] = 17, ["name"] = "building_blocks:hardwood", ["z"] = 4, ["param1"] = 15}, {["x"] = 9, ["meta"] = {["inventory"] = {}, ["fields"] = {}}, ["y"] = 17, ["name"] = "building_blocks:hardwood", ["z"] = 5, ["param1"] = 15}, {["x"] = 9, ["meta"] = {["inventory"] = {}, ["fields"] = {}}, ["y"] = 17, ["name"] = "building_blocks:hardwood", ["z"] = 6, ["param1"] = 15}, {["x"] = 9, ["meta"] = {["inventory"] = {}, ["fields"] = {}}, ["y"] = 17, ["name"] = "building_blocks:hardwood", ["z"] = 7, ["param1"] = 15}, {["x"] = 9, ["meta"] = {["inventory"] = {}, ["fields"] = {}}, ["y"] = 17, ["name"] = "building_blocks:hardwood", ["z"] = 8, ["param1"] = 15}, {["x"] = 9, ["meta"] = {["inventory"] = {}, ["fields"] = {}}, ["y"] = 17, ["name"] = "building_blocks:hardwood", ["z"] = 9, ["param1"] = 15}, {["x"] = 9, ["meta"] = {["inventory"] = {}, ["fields"] = {}}, ["y"] = 17, ["name"] = "building_blocks:hardwood", ["z"] = 10, ["param1"] = 15}, {["x"] = 9, ["meta"] = {["inventory"] = {}, ["fields"] = {}}, ["y"] = 17, ["name"] = "building_blocks:hardwood", ["z"] = 11, ["param1"] = 15}, {["x"] = 9, ["meta"] = {["inventory"] = {}, ["fields"] = {}}, ["y"] = 17, ["name"] = "building_blocks:hardwood", ["z"] = 12, ["param1"] = 15}, {["x"] = 9, ["meta"] = {["inventory"] = {}, ["fields"] = {}}, ["param2"] = 22, ["y"] = 17, ["name"] = "building_blocks:slope_hardwood_half_raised", ["z"] = 13, ["param1"] = 46}, {["x"] = 9, ["meta"] = {["inventory"] = {}, ["fields"] = {}}, ["y"] = 18, ["name"] = "ethereal:fence_redwood", ["z"] = 3, ["param1"] = 15}, {["x"] = 9, ["meta"] = {["inventory"] = {}, ["fields"] = {}}, ["param2"] = 9, ["y"] = 18, ["name"] = "moreblocks:panel_wood_tile_full", ["z"] = 5, ["param1"] = 29}, {["x"] = 9, ["meta"] = {["inventory"] = {}, ["fields"] = {}}, ["param2"] = 7, ["y"] = 18, ["name"] = "moreblocks:slab_coal_glass_1", ["z"] = 6, ["param1"] = 44}, {["x"] = 9, ["meta"] = {["inventory"] = {["recycle"] = {""}, ["output"] = {"building_blocks:micro_hardwood_1 20", "building_blocks:panel_hardwood_1 20", "building_blocks:micro_hardwood_2 20", "building_blocks:panel_hardwood_2 20", "building_blocks:micro_hardwood_4 20", "building_blocks:panel_hardwood_4 20", "building_blocks:micro_hardwood 20", "building_blocks:panel_hardwood 20", "building_blocks:micro_hardwood_12 20", "building_blocks:panel_hardwood_12 20", "building_blocks:micro_hardwood_14 20", "building_blocks:panel_hardwood_14 20", "building_blocks:micro_hardwood_15 20", "building_blocks:panel_hardwood_15 20", "building_blocks:stair_hardwood_outer 20", "building_blocks:stair_hardwood 20", "building_blocks:stair_hardwood_inner 20", "building_blocks:slab_hardwood_1 20", "building_blocks:slab_hardwood_2 20", "building_blocks:slab_hardwood_quarter 20", "building_blocks:slab_hardwood 20", "building_blocks:slab_hardwood_three_quarter 20", "building_blocks:slab_hardwood_14 20", "building_blocks:slab_hardwood_15 20", "building_blocks:slab_hardwood_two_sides 20", "building_blocks:slab_hardwood_three_sides 20", "building_blocks:slab_hardwood_three_sides_u 20", "building_blocks:stair_hardwood_half 20", "building_blocks:stair_hardwood_alt_1 20", "building_blocks:stair_hardwood_alt_2 20", "building_blocks:stair_hardwood_alt_4 20", "building_blocks:stair_hardwood_alt 20", "building_blocks:slope_hardwood 20", "building_blocks:slope_hardwood_half 20", "building_blocks:slope_hardwood_half_raised 20", "building_blocks:slope_hardwood_inner 20", "building_blocks:slope_hardwood_inner_half 20", "building_blocks:slope_hardwood_inner_half_raised 20", "building_blocks:slope_hardwood_inner_cut 20", "building_blocks:slope_hardwood_inner_cut_half 20", "building_blocks:slope_hardwood_inner_cut_half_raised 20", "building_blocks:slope_hardwood_outer 20", "building_blocks:slope_hardwood_outer_half 20", "building_blocks:slope_hardwood_outer_half_raised 20", "building_blocks:slope_hardwood_outer_cut 20", "building_blocks:slope_hardwood_outer_cut_half 20", "building_blocks:slope_hardwood_outer_cut_half_raised 20", "building_blocks:slope_hardwood_cut 20"}, ["input"] = {"building_blocks:hardwood 95"}, ["micro"] = {""}}, ["fields"] = {["max_offered"] = "20", ["anz"] = "760", ["infotext"] = "Circular Saw is working on hardwood (owned by tomraceror)", ["owner"] = "tomraceror", ["formspec"] = "size[11,10]bgcolor[#08080899;false]label[0,0;Input\
material]list[current_name;input;1.5,0;1,1;]label[0,1;Left-over]list[current_name;micro;1.5,1;1,1;]label[0,2;Recycle\
output]list[current_name;recycle;1.5,2;1,1;]field[0.3,3.5;1,1;max_offered;Max:;${max_offered}]button[1,3.2;1,1;Set;Set]list[current_name;output;2.8,0;8,6;]list[current_player;main;1.5,6.25;8,4;]"}}, ["param2"] = 1, ["y"] = 18, ["name"] = "moreblocks:circular_saw", ["z"] = 7, ["param1"] = 59}, {["x"] = 9, ["meta"] = {["inventory"] = {["recycle"] = {""}, ["output"] = {"moreblocks:micro_copperpatina_1 20", "moreblocks:panel_copperpatina_1 20", "moreblocks:micro_copperpatina_2 20", "moreblocks:panel_copperpatina_2 20", "moreblocks:micro_copperpatina_4 20", "moreblocks:panel_copperpatina_4 20", "moreblocks:micro_copperpatina 20", "moreblocks:panel_copperpatina 20", "moreblocks:micro_copperpatina_12 20", "moreblocks:panel_copperpatina_12 20", "moreblocks:micro_copperpatina_14 20", "moreblocks:panel_copperpatina_14 20", "moreblocks:micro_copperpatina_15 20", "moreblocks:panel_copperpatina_15 20", "moreblocks:stair_copperpatina_outer 20", "moreblocks:stair_copperpatina 20", "moreblocks:stair_copperpatina_inner 20", "moreblocks:slab_copperpatina_1 20", "moreblocks:slab_copperpatina_2 20", "moreblocks:slab_copperpatina_quarter 20", "moreblocks:slab_copperpatina 20", "moreblocks:slab_copperpatina_three_quarter 20", "moreblocks:slab_copperpatina_14 20", "moreblocks:slab_copperpatina_15 20", "moreblocks:slab_copperpatina_two_sides 20", "moreblocks:slab_copperpatina_three_sides 20", "moreblocks:slab_copperpatina_three_sides_u 20", "moreblocks:stair_copperpatina_half 20", "moreblocks:stair_copperpatina_alt_1 20", "moreblocks:stair_copperpatina_alt_2 20", "moreblocks:stair_copperpatina_alt_4 20", "moreblocks:stair_copperpatina_alt 20", "moreblocks:slope_copperpatina 20", "moreblocks:slope_copperpatina_half 20", "moreblocks:slope_copperpatina_half_raised 20", "moreblocks:slope_copperpatina_inner 20", "moreblocks:slope_copperpatina_inner_half 20", "moreblocks:slope_copperpatina_inner_half_raised 20", "moreblocks:slope_copperpatina_inner_cut 20", "moreblocks:slope_copperpatina_inner_cut_half 20", "moreblocks:slope_copperpatina_inner_cut_half_raised 20", "moreblocks:slope_copperpatina_outer 20", "moreblocks:slope_copperpatina_outer_half 20", "moreblocks:slope_copperpatina_outer_half_raised 20", "moreblocks:slope_copperpatina_outer_cut 20", "moreblocks:slope_copperpatina_outer_cut_half 20", "moreblocks:slope_copperpatina_outer_cut_half_raised 20", "moreblocks:slope_copperpatina_cut 20"}, ["input"] = {"moreblocks:copperpatina 77"}, ["micro"] = {"moreblocks:micro_copperpatina 6"}}, ["fields"] = {["max_offered"] = "20", ["anz"] = "622", ["infotext"] = "Circular Saw is working on copperpatina (owned by tomraceror)", ["owner"] = "tomraceror", ["formspec"] = "size[11,10]bgcolor[#08080899;false]label[0,0;Input\
material]list[current_name;input;1.5,0;1,1;]label[0,1;Left-over]list[current_name;micro;1.5,1;1,1;]label[0,2;Recycle\
